Workbook

Sheet Existing capacity
C1: 2020
A2: Technology | B2: Model tech | C2: exs cap Munits | D2: Efficiency | E2: ann sec energy PJ | F2: annual act PJ/Munit | G2: Arb. c2a PJ/Munityr | H2: Annual CF | I2: Est unit cap kbtu/hr | J2: est c2a PJ/Munityr | K2: ACF
A3: Heating Oil – Normal Efficiency | C3: =stock!W28/1000 -> 0 | D3: =efficiency!W14/100 -> 0.6 | E3: ='secondary energy'!W15 -> 0 | F3: =D3*E3/C3 -> #DIV/0! | G3: 1000 | H3: =F3/G3 -> #DIV/0!
A4: Heating Oil – Medium Efficiency | B4: R_SPH_OIL_MEF | C4: =stock!W29/1000 -> 0.132248 | D4: =efficiency!W15/100 -> 0.78 | E4: ='secondary energy'!W16 -> 3.759117 | F4: =D4*E4/C4 -> 22.171309 | G4: 1000 | H4: =F4/G4 -> 0.022171309 | I4: 105 | J4: =I4*$B$21*$B$22*1000000 -> 970.44014 | K4: =F4/J4 -> 0.022846653
A5: Heating Oil – High Efficiency | C5: =stock!W30/1000 -> 0 | D5: =efficiency!W16/100 -> 0.85 | E5: ='secondary energy'!W17 -> 0 | F5: =D5*E5/C5 -> #DIV/0! | G5: 1000 | H5: =F5/G5 -> #DIV/0!
A6: Natural Gas – Normal Efficiency | C6: =stock!W31/1000 -> 0 | D6: =efficiency!W17/100 -> 0.62 | E6: ='secondary energy'!W18 -> 0 | F6: =D6*E6/C6 -> #DIV/0! | G6: 1000 | H6: =F6/G6 -> #DIV/0!
A7: Natural Gas – Medium Efficiency | B7: R_SPH_NGS_MEF | C7: =stock!W32/1000 -> 0.72494 | D7: =efficiency!W18/100 -> 0.8 | E7: ='secondary energy'!W19 -> 49.475327 | F7: =D7*E7/C7 -> 54.597983 | G7: 1000 | H7: =F7/G7 -> 0.054597983 | I7: 80 | J7: =I7*$B$21*$B$22*1000000 -> 739.38296 | K7: =F7/J7 -> 0.07384263
A8: Natural Gas – High Efficiency | B8: R_SPH_NGS_HEF | C8: =stock!W33/1000 -> 3.099763 | D8: =efficiency!W19/100 -> 0.9 | E8: ='secondary energy'!W20 -> 184.52888 | F8: =D8*E8/C8 -> 53.576996 | G8: 1000 | H8: =F8/G8 -> 0.053576996 | I8: 80 | J8: =I8*$B$21*$B$22*1000000 -> 739.38296 | K8: =F8/J8 -> 0.072461767
A9: Electric | B9: R_SPH_ELC_EXS | C9: =stock!W34/1000 -> 0.983798 | D9: =efficiency!W20/100 -> 1 | E9: ='secondary energy'!W21 -> 34.435598 | F9: =D9*E9/C9 -> 35.002712 | G9: 1000 | H9: =F9/G9 -> 0.035002712 | I9: 68 | J9: =I9*$B$21*$B$22*1000000 -> 628.47552 | K9: =F9/J9 -> 0.055694631
A10: Heat Pump | B10: R_SPH_HP_EXS | C10: =stock!W35/1000 -> 0.394619 | D10: =efficiency!W21/100 -> 1.9 | E10: ='secondary energy'!W22 -> 9.790103 | F10: =D10*E10/C10 -> 47.137101 | G10: 1000 | H10: =F10/G10 -> 0.047137101 | I10: 36 | J10: =I10*$B$21*$B$22*1000000 -> 332.72233 | K10: =F10/J10 -> 0.14167099
A11: Other (LPG) | B11: R_SPH_LPG_MEF | C11: =stock!W36/1000 -> 0.180887 | D11: =efficiency!W22/100 -> 0.5 | E11: ='secondary energy'!W23 -> 7.932062 | F11: =D11*E11/C11 -> 21.925462 | G11: 1000 | H11: =F11/G11 -> 0.021925462 | I11: 80 | J11: =I11*$B$21*$B$22*1000000 -> 739.38296 | K11: =F11/J11 -> 0.029653729
A12: Wood | B12: R_SPH_WOD_EXS | C12: =stock!W37/1000 -> 0.027367 | D12: =efficiency!W23/100 -> 0.5 | E12: ='secondary energy'!W24 -> 1.468934 | F12: =D12*E12/C12 -> 26.837688 | G12: 1000 | H12: =F12/G12 -> 0.026837688 | I12: 50 | J12: =I12*$B$21*$B$22*1000000 -> 462.11435 | K12: =F12/J12 -> 0.058075858
A13: Dual Systems | C13: =stock!W38/1000 -> 0 | F13: =D13*E13/C13 -> #DIV/0! | H13: =F13/G13 -> #DIV/0!
A14: Wood/Electric | B14: R_SPH_WOD_ELC | C14: =stock!W39/1000 -> 0.124442 | D14: =efficiency!W27/100 -> 0.5 | E14: ='secondary energy'!W26 -> 14.379021 | F14: =D14*E14/C14 -> 57.773987 | G14: 1000 | H14: =F14/G14 -> 0.057773987 | I14: 50 | J14: =I14*$B$21*$B$22*1000000 -> 462.11435 | K14: =F14/J14 -> 0.12502098
A15: Wood/Heating Oil | B15: R_SPH_WOD_OIL | C15: =stock!W40/1000 -> 0.11401 | D15: =efficiency!W30/100 -> 0.78 | E15: ='secondary energy'!W27 -> 5.788741 | F15: =D15*E15/C15 -> 39.603701 | G15: 1000 | H15: =F15/G15 -> 0.039603701 | I15: 105 | J15: =I15*$B$21*$B$22*1000000 -> 970.44014 | K15: =F15/J15 -> 0.04081004
A16: Natural Gas/Electric | B16: R_SPH_NGS_ELC | C16: =stock!W41/1000 -> 0.033182 | D16: =efficiency!W35/100 -> 0.8 | E16: ='secondary energy'!W28 -> 2.36032 | F16: =D16*E16/C16 -> 56.906033 | G16: 1000 | H16: =F16/G16 -> 0.056906033 | I16: 80 | J16: =I16*$B$21*$B$22*1000000 -> 739.38296 | K16: =F16/J16 -> 0.07696422
A17: Heating Oil/Electric | B17: R_SPH_OIL_ELC | C17: =stock!W42/1000 -> 0.020537 | D17: =efficiency!W39/100 -> 0.78 | E17: ='secondary energy'!W29 -> 0.713613 | F17: =D17*E17/C17 -> 27.103186 | G17: 1000 | H17: =F17/G17 -> 0.027103186 | I17: 105 | J17: =I17*$B$21*$B$22*1000000 -> 970.44014 | K17: =F17/J17 -> 0.027928757
A19: Population index | C19: 1 | E19: =SUM(E3:E17) -> 314.63171 | F19: DEMAND
A21: GW = | B21: =0.293071*1000/1000000000 -> 2.93071e-07 | C21: x kBtu/h
A22: PJ = | B22: =8760*3600/1000000 -> 31.536 | C22: x GWy
A24: Have to do it this way because we don't know the capacity factor for secondary energy use
A25: Assume an arbitrary 1000 PJ/Munityr unit capacity and use this to calculate annual capacity factor which defines actual energy output per unit

Sheet stock
A5: Residential Sector
A7: Ontario
A8: Table 21: Heating System Stock by Building Type and Heating System Type
C11: 2000 | D11: 2001 | E11: 2002 | F11: 2003 | G11: 2004 | H11: 2005 | I11: 2006 | J11: 2007 | K11: 2008 | L11: 2009 | M11: 2010 | N11: 2011 | O11: 2012 | P11: 2013 | Q11: 2014 | R11: 2015 | S11: 2016 | T11: 2017 | U11: 2018 | V11: 2019 | W11: 2020
B13: Total Heating System Stock (thousands) | C13: 4467.553 | D13: 4534.144 | E13: 4613.028 | F13: 4686.675 | G13: 4767.289 | H13: 4845.367 | I13: 4916.95 | J13: 4978.142 | K13: 5042.746 | L13: 5095.007 | M13: 5153.651 | N13: 5211.112 | O13: 5266.254 | P13: 5321.668 | Q13: 5374.794 | R13: 5443.987 | S13: 5511.758 | T13: 5577.315 | U13: 5668.303 | V13: 5752.217 | W13: 5835.796
B14: Heating System Stock by Building Type (thousands)
B15: Single Detached | C15: 2526.949 | D15: 2566.514 | E15: 2611.338 | F15: 2655.441 | G15: 2701.032 | H15: 2741.481 | I15: 2778.509 | J15: 2812.05 | K15: 2843.692 | L15: 2865.734 | M15: 2890.378 | N15: 2912.26 | O15: 2935.66 | P15: 2955.864 | Q15: 2975.8 | R15: 2993.051 | S15: 3021.265 | T15: 3046.719 | U15: 3090.839 | V15: 3139.107 | W15: 3175.862
B16: Single Attached | C16: 625.411 | D16: 645.087 | E16: 663.29 | F16: 679.781 | G16: 698.259 | H16: 714.881 | I16: 731.061 | J16: 745.749 | K16: 759.567 | L16: 771.992 | M16: 784.059 | N16: 796.103 | O16: 808.17 | P16: 821.436 | Q16: 833.815 | R16: 844.348 | S16: 856.246 | T16: 870.625 | U16: 887.782 | V16: 901.036 | W16: 916.234
B17: Apartments | C17: 1290.324 | D17: 1297.748 | E17: 1313.516 | F17: 1326.431 | G17: 1342.798 | H17: 1363.65 | I17: 1381.886 | J17: 1394.728 | K17: 1413.762 | L17: 1431.509 | M17: 1453.373 | N17: 1476.855 | O17: 1496.436 | P17: 1518.268 | Q17: 1538.972 | R17: 1580.292 | S17: 1607.85 | T17: 1633.453 | U17: 1663.062 | V17: 1685.378 | W17: 1716.934
B18: Mobile Homes | C18: 24.869 | D18: 24.795 | E18: 24.884 | F18: 25.022 | G18: 25.2 | H18: 25.356 | I18: 25.495 | J18: 25.615 | K18: 25.725 | L18: 25.773 | M18: 25.841 | N18: 25.894 | O18: 25.988 | P18: 26.101 | Q18: 26.207 | R18: 26.296 | S18: 26.398 | T18: 26.518 | U18: 26.62 | V18: 26.696 | W18: 26.766
B20: Shares (%)
B21: Single Detached | C21: 56.562255 | D21: 56.604153 | E21: 56.607896 | F21: 56.65939 | G21: 56.657609 | H21: 56.57943 | I21: 56.508787 | J21: 56.487955 | K21: 56.391737 | L21: 56.245926 | M21: 56.084088 | N21: 55.885584 | O21: 55.744755 | P21: 55.543932 | Q21: 55.365839 | R21: 54.979027 | S21: 54.814898 | T21: 54.626989 | U21: 54.528479 | V21: 54.57212 | W21: 54.420382
B22: Single Attached | C22: 13.998961 | D22: 14.227314 | E22: 14.378624 | F22: 14.504547 | G22: 14.646877 | H22: 14.753906 | I22: 14.86818 | J22: 14.980468 | K22: 15.062566 | L22: 15.151929 | M22: 15.213659 | N22: 15.277027 | O22: 15.346202 | P22: 15.435686 | Q22: 15.513431 | R22: 15.509735 | S22: 15.534897 | T22: 15.610109 | U22: 15.662218 | V22: 15.664151 | W22: 15.70024
B23: Apartments | C23: 28.882119 | D23: 28.621673 | E23: 28.474052 | F23: 28.302176 | G23: 28.166906 | H23: 28.143369 | I23: 28.104529 | J23: 28.017035 | K23: 28.035554 | L23: 28.096303 | M23: 28.200836 | N23: 28.340494 | O23: 28.415564 | P23: 28.529923 | Q23: 28.633131 | R23: 29.028207 | S23: 29.171269 | T23: 29.28744 | U23: 29.339677 | V23: 29.299622 | W23: 29.420732
B24: Mobile Homes | C24: 0.556666 | D24: =SUM(D4:D18) -> 11069.288 | F24: 0.533887 | G24: 0.528608 | H24: 0.523295 | I24: 0.518503 | J24: 0.514541 | K24: 0.510142 | L24: 0.505841 | M24: 0.501416 | N24: 0.496895 | O24: 0.49348 | P24: 0.490459 | Q24: 0.487599 | R24: 0.483031 | S24: 0.478935 | T24: 0.475462 | U24: 0.469627 | V24: 0.464107 | W24: 0.458646
B27: Heating System Stock by Heating System Type (thousands)
B28: Heating Oil – Normal Efficiency | C28: 153.546 | D28: 123.231 | E28: 89.437 | F28: 64.69 | G28: 47.129 | H28: 38.216 | I28: 26.773 | J28: 14.472 | K28: 7.719 | L28: 3.032 | M28: 0 | N28: 0 | O28: 0 | P28: 0 | Q28: 0 | R28: 0 | S28: 0 | T28: 0 | U28: 0 | V28: 0 | W28: 0
B29: Heating Oil – Medium Efficiency | C29: 210.217 | D29: 227.386 | E29: 230.43 | F29: 236.247 | G29: 246.208 | H29: 251.009 | I29: 250.351 | J29: 249.558 | K29: 248.707 | L29: 247.561 | M29: 245.195 | N29: 241.874 | O29: 237.329 | P29: 231.07 | Q29: 221.476 | R29: 210.204 | S29: 197.191 | T29: 182.553 | U29: 166.871 | V29: 149.891 | W29: 132.248
B30: Heating Oil – High Efficiency | C30: 0 | D30: 0 | E30: 0 | F30: 0 | G30: 0 | H30: 0 | I30: 0 | J30: 0 | K30: 0 | L30: 0 | M30: 0 | N30: 0 | O30: 0 | P30: 0 | Q30: 0 | R30: 0 | S30: 0 | T30: 0 | U30: 0 | V30: 0 | W30: 0
B31: Natural Gas – Normal Efficiency | C31: 1355.734 | D31: 1275.898 | E31: 1188.647 | F31: 1092.807 | G31: 987.61 | H31: 877.191 | I31: 764.428 | J31: 652.094 | K31: 544.606 | L31: 438.567 | M31: 341.529 | N31: 249.113 | O31: 163.071 | P31: 85.962 | Q31: 56.207 | R31: 31.045 | S31: 14.971 | T31: 4.617 | U31: 0 | V31: 0 | W31: 0
B32: Natural Gas – Medium Efficiency | C32: 869.081 | D32: 930.786 | E32: 997.994 | F32: 1055.411 | G32: 1108.441 | H32: 1152.533 | I32: 1190.656 | J32: 1223.613 | K32: 1240.081 | L32: 1246.952 | M32: 1235.922 | N32: 1220.651 | O32: 1200.055 | P32: 1171.374 | Q32: 1125.499 | R32: 1071.29 | S32: 1008.432 | T32: 938.822 | U32: 867.179 | V32: 794.917 | W32: 724.94
B33: Natural Gas – High Efficiency | C33: 694.127 | D33: 778.226 | E33: 884.015 | F33: 988.872 | G33: 1105.821 | H33: 1224.148 | I33: 1355.326 | J33: 1475.251 | K33: 1602.132 | L33: 1722.632 | M33: 1856.56 | N33: 1986.275 | O33: 2112.621 | P33: 2239.154 | Q33: 2347.467 | R33: 2469.622 | S33: 2587.892 | T33: 2703.891 | U33: 2843.232 | V33: 2972.992 | W33: 3099.763
B34: Electric | C34: 673.159 | D34: 673.07 | E34: 678.347 | F34: 683.613 | G34: 690.166 | H34: 699.87 | I34: 712.543 | J34: 725.917 | K34: 744.312 | L34: 763.527 | M34: 785.015 | N34: 806.035 | O34: 826.882 | P34: 848.072 | Q34: 864.162 | R34: 885.104 | S34: 905.783 | T34: 927.184 | U34: 946.442 | V34: 964.551 | W34: 983.798
B35: Heat Pump | C35: 187.794 | D35: 198.323 | E35: 210.001 | F35: 221.708 | G35: 233.145 | H35: 244.469 | I35: 254.592 | J35: 265.129 | K35: 275.484 | L35: 285.5 | M35: 294.79 | N35: 304.249 | O35: 314.12 | P35: 323.619 | Q35: 330.137 | R35: 336.927 | S35: 345.885 | T35: 354.955 | U35: 368.205 | V35: 381.839 | W35: 394.619
B36: Other1 | C36: 56.476 | D36: 56.271 | E36: 56.477 | F36: 56.675 | G36: 57.512 | H36: 59.208 | I36: 61.8 | J36: 65.283 | K36: 70.061 | L36: 75.929 | M36: 83.091 | N36: 90.919 | O36: 99.505 | P36: 108.929 | Q36: 118.464 | R36: 129.471 | S36: 141.597 | T36: 154.958 | U36: 163.164 | V36: 171.716 | W36: 180.887
B37: Wood | C37: 41.876 | D37: 40.74 | E37: 42.482 | F37: 46.22 | G37: 46.545 | H37: 50.045 | I37: 48.678 | J37: 51.489 | K37: 50.635 | L37: 48.585 | M37: 45.757 | N37: 43.034 | O37: 40.372 | P37: 37.915 | Q37: 35.553 | R37: 33.612 | S37: 31.517 | T37: 29.532 | U37: 28.846 | V37: 28.018 | W37: 27.367
B38: Dual Systems
B39: Wood/Electric | C39: 100.317 | D39: 102.115 | E39: 104.058 | F39: 106.111 | G39: 107.729 | H39: 109.204 | I39: 110.3 | J39: 111.582 | K39: 112.932 | L39: 114.3 | M39: 115.393 | N39: 116.536 | O39: 117.756 | P39: 118.946 | Q39: 118.776 | R39: 118.89 | S39: 119.414 | T39: 120.177 | U39: 121.494 | V39: 122.982 | W39: 124.442
B40: Wood/Heating Oil | C40: 91.425 | D40: 93.081 | E40: 94.87 | F40: 96.762 | G40: 98.263 | H40: 99.637 | I40: 100.667 | J40: 101.866 | K40: 103.125 | L40: 104.4 | M40: 105.424 | N40: 106.493 | O40: 107.632 | P40: 108.745 | Q40: 108.638 | R40: 108.786 | S40: 109.304 | T40: 110.038 | U40: 111.268 | V40: 112.651 | W40: 114.01
B41: Natural Gas/Electric | C41: 20.456 | D41: 21.229 | E41: 22.027 | F41: 22.843 | G41: 23.582 | H41: 24.294 | I41: 24.934 | J41: 25.605 | K41: 26.286 | L41: 26.969 | M41: 27.58 | N41: 28.192 | O41: 28.819 | P41: 29.441 | Q41: 29.79 | R41: 30.195 | S41: 30.669 | T41: 31.189 | U41: 31.833 | V41: 32.507 | W41: 33.182
B42: Heating Oil/Electric | C42: 13.345 | D42: 13.787 | E42: 14.245 | F42: 14.715 | G42: 15.137 | H42: 15.542 | I42: 15.902 | J42: 16.281 | K42: 16.667 | L42: 17.054 | M42: 17.396 | N42: 17.74 | O42: 18.092 | P42: 18.442 | Q42: 18.624 | R42: 18.841 | S42: 19.105 | T42: 19.4 | U42: 19.767 | V42: 20.152 | W42: 20.537
B44: Shares (%)
B45: Heating Oil – Normal Efficiency | C45: 3.436909 | D45: 2.717855 | E45: 1.938783 | F45: 1.380304 | G45: 0.988596 | H45: 0.788709 | I45: 0.544512 | J45: 0.29072 | K45: 0.153068 | L45: 0.059513 | M45: 0 | N45: 0 | O45: 0 | P45: 0 | Q45: 0 | R45: 0 | S45: 0 | T45: 0 | U45: 0 | V45: 0 | W45: 0
B46: Heating Oil – Medium Efficiency | C46: 4.705409 | D46: 5.014964 | E46: 4.995202 | F46: 5.04082 | G46: 5.164527 | H46: 5.18039 | I46: 5.091588 | J46: 5.013085 | K46: 4.931974 | L46: 4.858889 | M46: 4.757687 | N46: 4.641503 | O46: 4.506594 | P46: 4.342066 | Q46: 4.120633 | R46: 3.861217 | S46: 3.577644 | T46: 3.27313 | U46: 2.943935 | V46: 2.605792 | W46: 2.266159
B47: Heating Oil – High Efficiency | C47: 0 | D47: 0 | E47: 0 | F47: 0 | G47: 0 | H47: 0 | I47: 0 | J47: 0 | K47: 0 | L47: 0 | M47: 0 | N47: 0 | O47: 0 | P47: 0 | Q47: 0 | R47: 0 | S47: 0 | T47: 0 | U47: 0 | V47: 0 | W47: 0
B48: Natural Gas – Normal Efficiency | C48: 30.346233 | D48: 28.139778 | E48: 25.767166 | F48: 23.317326 | G48: 20.716389 | H48: 18.103707 | I48: 15.546784 | J48: 13.099143 | K48: 10.799792 | L48: 8.607775 | M48: 6.626932 | N48: 4.780418 | O48: 3.096523 | P48: 1.61532 | Q48: 1.045749 | R48: 0.570261 | S48: 0.271612 | T48: 0.082777 | U48: 0 | V48: 0 | W48: 0
B49: Natural Gas – Medium Efficiency | C49: 19.453173 | D49: 20.528379 | E49: 21.63424 | F49: 22.519395 | G49: 23.250977 | H49: 23.786297 | I49: 24.215336 | J49: 24.57972 | K49: 24.591391 | L49: 24.474003 | M49: 23.981477 | N49: 23.423995 | O49: 22.787649 | P49: 22.011404 | Q49: 20.94032 | R49: 19.678407 | S49: 18.296007 | T49: 16.832861 | U49: 15.298734 | V49: 13.819312 | W49: 12.422298
B50: Natural Gas – High Efficiency | C50: 15.537082 | D50: 17.163686 | E50: 19.163437 | F50: 21.099656 | G50: 23.196008 | H50: 25.264303 | I50: 27.564375 | J50: 29.634569 | K50: 31.771018 | L50: 33.810201 | M50: 36.024172 | N50: 38.116155 | O50: 40.116198 | P50: 42.076174 | Q50: 43.675487 | R50: 45.364218 | S50: 46.952212 | T50: 48.480157 | U50: 50.160208 | V50: 51.684275 | W50: 53.116374
B51: Electric | C51: 15.067732 | D51: 14.844475 | E51: 14.705024 | F51: 14.586314 | G51: 14.477114 | H51: 14.444108 | I51: 14.491562 | J51: 14.582084 | K51: 14.760047 | L51: 14.98579 | M51: 15.232216 | N51: 15.46763 | O51: 15.701515 | P51: 15.936204 | Q51: 16.078056 | R51: 16.258378 | S51: 16.433642 | T51: 16.6242 | U51: 16.697096 | V51: 16.768342 | W51: 16.857996
B52: Heat Pump | C52: 4.203499 | D52: 4.37399 | E52: 4.552356 | F52: 4.730612 | G52: 4.890514 | H52: 5.045426 | I52: 5.177842 | J52: 5.325866 | K52: 5.462981 | L52: 5.603522 | M52: 5.720025 | N52: 5.838463 | O52: 5.964781 | P52: 6.081152 | Q52: 6.142311 | R52: 6.188983 | S52: 6.275396 | T52: 6.364259 | U52: 6.495868 | V52: 6.638112 | W52: 6.762046
...

Sheet efficiency
A5: Residential Sector
A7: Ontario
A8: Table 26: Heating System Stock Efficiencies
C11: 2000 | D11: 2001 | E11: 2002 | F11: 2003 | G11: 2004 | H11: 2005 | I11: 2006 | J11: 2007 | K11: 2008 | L11: 2009 | M11: 2010 | N11: 2011 | O11: 2012 | P11: 2013 | Q11: 2014 | R11: 2015 | S11: 2016 | T11: 2017 | U11: 2018 | V11: 2019 | W11: 2020
B13: Heating System Stock Efficiencies by System Type (%)
B14: Heating Oil – Normal Efficiency | C14: 60 | D14: 60 | E14: 60 | F14: 60 | G14: 60 | H14: 60 | I14: 60 | J14: 60 | K14: 60 | L14: 60 | M14: 60 | N14: 60 | O14: 60 | P14: 60 | Q14: 60 | R14: 60 | S14: 60 | T14: 60 | U14: 60 | V14: 60 | W14: 60
B15: Heating Oil – Medium Efficiency | C15: 78 | D15: 78 | E15: 78 | F15: 78 | G15: 78 | H15: 78 | I15: 78 | J15: 78 | K15: 78 | L15: 78 | M15: 78 | N15: 78 | O15: 78 | P15: 78 | Q15: 78 | R15: 78 | S15: 78 | T15: 78 | U15: 78 | V15: 78 | W15: 78
B16: Heating Oil – High Efficiency | C16: 85 | D16: 85 | E16: 85 | F16: 85 | G16: 85 | H16: 85 | I16: 85 | J16: 85 | K16: 85 | L16: 85 | M16: 85 | N16: 85 | O16: 85 | P16: 85 | Q16: 85 | R16: 85 | S16: 85 | T16: 85 | U16: 85 | V16: 85 | W16: 85
B17: Natural Gas – Normal Efficiency | C17: 62 | D17: 62 | E17: 62 | F17: 62 | G17: 62 | H17: 62 | I17: 62 | J17: 62 | K17: 62 | L17: 62 | M17: 62 | N17: 62 | O17: 62 | P17: 62 | Q17: 62 | R17: 62 | S17: 62 | T17: 62 | U17: 62 | V17: 62 | W17: 62
B18: Natural Gas – Medium Efficiency | C18: 79 | D18: 80 | E18: 80 | F18: 80 | G18: 80 | H18: 80 | I18: 80 | J18: 80 | K18: 80 | L18: 80 | M18: 80 | N18: 80 | O18: 80 | P18: 80 | Q18: 80 | R18: 80 | S18: 80 | T18: 80 | U18: 80 | V18: 80 | W18: 80
B19: Natural Gas – High Efficiency | C19: 90 | D19: 90 | E19: 90 | F19: 90 | G19: 90 | H19: 90 | I19: 90 | J19: 90 | K19: 90 | L19: 90 | M19: 90 | N19: 90 | O19: 90 | P19: 90 | Q19: 90 | R19: 90 | S19: 90 | T19: 90 | U19: 90 | V19: 90 | W19: 90
B20: Electric | C20: 100 | D20: 100 | E20: 100 | F20: 100 | G20: 100 | H20: 100 | I20: 100 | J20: 100 | K20: 100 | L20: 100 | M20: 100 | N20: 100 | O20: 100 | P20: 100 | Q20: 100 | R20: 100 | S20: 100 | T20: 100 | U20: 100 | V20: 100 | W20: 100
B21: Heat Pump | C21: 190 | D21: 190 | E21: 190 | F21: 190 | G21: 190 | H21: 190 | I21: 190 | J21: 190 | K21: 190 | L21: 190 | M21: 190 | N21: 190 | O21: 190 | P21: 190 | Q21: 190 | R21: 190 | S21: 190 | T21: 190 | U21: 190 | V21: 190 | W21: 190
B22: Other1 | C22: 50 | D22: 50 | E22: 50 | F22: 50 | G22: 50 | H22: 50 | I22: 50 | J22: 50 | K22: 50 | L22: 50 | M22: 50 | N22: 50 | O22: 50 | P22: 50 | Q22: 50 | R22: 50 | S22: 50 | T22: 50 | U22: 50 | V22: 50 | W22: 50
B23: Wood | C23: 50 | D23: 50 | E23: 50 | F23: 50 | G23: 50 | H23: 50 | I23: 50 | J23: 50 | K23: 50 | L23: 50 | M23: 50 | N23: 50 | O23: 50 | P23: 50 | Q23: 50 | R23: 50 | S23: 50 | T23: 50 | U23: 50 | V23: 50 | W23: 50
B25: Dual Heating Systems Electric/Wood
B26: Electricity | C26: 100 | D26: 100 | E26: 100 | F26: 100 | G26: 100 | H26: 100 | I26: 100 | J26: 100 | K26: 100 | L26: 100 | M26: 100 | N26: 100 | O26: 100 | P26: 100 | Q26: 100 | R26: 100 | S26: 100 | T26: 100 | U26: 100 | V26: 100 | W26: 100
B27: Wood | C27: 50 | D27: 50 | E27: 50 | F27: 50 | G27: 50 | H27: 50 | I27: 50 | J27: 50 | K27: 50 | L27: 50 | M27: 50 | N27: 50 | O27: 50 | P27: 50 | Q27: 50 | R27: 50 | S27: 50 | T27: 50 | U27: 50 | V27: 50 | W27: 50
B29: Dual Heating Systems Heating Oil/Wood
B30: Heating Oil | C30: 78 | D30: 78 | E30: 78 | F30: 78 | G30: 78 | H30: 78 | I30: 78 | J30: 78 | K30: 78 | L30: 78 | M30: 78 | N30: 78 | O30: 78 | P30: 78 | Q30: 78 | R30: 78 | S30: 78 | T30: 78 | U30: 78 | V30: 78 | W30: 78
B31: Wood | C31: 57 | D31: 57 | E31: 57 | F31: 57 | G31: 57 | H31: 57 | I31: 57 | J31: 57 | K31: 57 | L31: 57 | M31: 57 | N31: 57 | O31: 57 | P31: 57 | Q31: 57 | R31: 57 | S31: 57 | T31: 57 | U31: 57 | V31: 57 | W31: 57
B33: Dual Heating Systems Electric/Natural Gas
B34: Electricity | C34: 100 | D34: 100 | E34: 100 | F34: 100 | G34: 100 | H34: 100 | I34: 100 | J34: 100 | K34: 100 | L34: 100 | M34: 100 | N34: 100 | O34: 100 | P34: 100 | Q34: 100 | R34: 100 | S34: 100 | T34: 100 | U34: 100 | V34: 100 | W34: 100
B35: Natural Gas | C35: 79 | D35: 80 | E35: 80 | F35: 80 | G35: 80 | H35: 80 | I35: 80 | J35: 80 | K35: 80 | L35: 80 | M35: 80 | N35: 80 | O35: 80 | P35: 80 | Q35: 80 | R35: 80 | S35: 80 | T35: 80 | U35: 80 | V35: 80 | W35: 80
B37: Dual Heating Systems Electric/Heating Oil
B38: Electricity | C38: 100 | D38: 100 | E38: 100 | F38: 100 | G38: 100 | H38: 100 | I38: 100 | J38: 100 | K38: 100 | L38: 100 | M38: 100 | N38: 100 | O38: 100 | P38: 100 | Q38: 100 | R38: 100 | S38: 100 | T38: 100 | U38: 100 | V38: 100 | W38: 100
B39: Heating Oil | C39: 78 | D39: 78 | E39: 78 | F39: 78 | G39: 78 | H39: 78 | I39: 78 | J39: 78 | K39: 78 | L39: 78 | M39: 78 | N39: 78 | O39: 78 | P39: 78 | Q39: 78 | R39: 78 | S39: 78 | T39: 78 | U39: 78 | V39: 78 | W39: 78
A41: 1) “Other” includes coal and propane.

Sheet secondary energy
A5: Residential Sector
A7: Ontario
A8: Table 8: Space Heating Secondary Energy Use by System Type
C11: 2000 | D11: 2001 | E11: 2002 | F11: 2003 | G11: 2004 | H11: 2005 | I11: 2006 | J11: 2007 | K11: 2008 | L11: 2009 | M11: 2010 | N11: 2011 | O11: 2012 | P11: 2013 | Q11: 2014 | R11: 2015 | S11: 2016 | T11: 2017 | U11: 2018 | V11: 2019 | W11: 2020
B13: Total Space Heating Energy Use (PJ) | C13: 344.74176 | D13: 316.39127 | E13: 332.69486 | F13: 365.83645 | G13: 352.28206 | H13: 359.02979 | I13: 324.91722 | J13: 367.27056 | K13: 376.66456 | L13: 358.11449 | M13: 337.04956 | N13: 365.51365 | O13: 322.33339 | P13: 374.39162 | Q13: 386.50565 | R13: 379.52621 | S13: 342.54088 | T13: 358.30311 | U13: 401.79915 | V13: 353.12348 | W13: 314.63171
B14: Energy Use by System Type (PJ)
B15: Heating Oil – Normal Efficiency | C15: 11.341737 | D15: 8.138384 | E15: 6.470584 | F15: 4.106963 | G15: 2.419252 | H15: 2.326737 | I15: 1.45747 | J15: 0.788887 | K15: 0.371198 | L15: 0.149759 | M15: 0 | N15: 0 | O15: 0 | P15: 0 | Q15: 0 | R15: 0 | S15: 0 | T15: 0 | U15: 0 | V15: 0 | W15: 0
B16: Heating Oil – Medium Efficiency | C16: 13.647463 | D16: 13.740637 | E16: 16.618813 | F16: 17.136997 | G16: 16.808618 | H16: 20.35566 | I16: 18.152396 | J16: 18.147202 | K16: 16.141672 | L16: 17.133406 | M16: 16.897257 | N16: 13.920483 | O16: 11.574112 | P16: 12.631125 | Q16: 11.269383 | R16: 10.163352 | S16: 7.379291 | T16: 6.231585 | U16: 5.984148 | V16: 4.82508 | W16: 3.759117
B17: Heating Oil – High Efficiency | C17: 0 | D17: 0 | E17: 0 | F17: 0 | G17: 0 | H17: 0 | I17: 0 | J17: 0 | K17: 0 | L17: 0 | M17: 0 | N17: 0 | O17: 0 | P17: 0 | Q17: 0 | R17: 0 | S17: 0 | T17: 0 | U17: 0 | V17: 0 | W17: 0
B18: Natural Gas – Normal Efficiency | C18: 130.33868 | D18: 112.63947 | E18: 109.47304 | F18: 111.83345 | G18: 95.352283 | H18: 85.098147 | I18: 66.013933 | J18: 64.316605 | K18: 54.721136 | L18: 40.01163 | M18: 28.30271 | N18: 22.175936 | O18: 11.331372 | P18: 5.147264 | Q18: 3.373086 | R18: 1.686067 | S18: 0.677377 | T18: 0.21598 | U18: 0 | V18: 0 | W18: 0
B19: Natural Gas – Medium Efficiency | C19: 66.914292 | D19: 65.158535 | E19: 73.009283 | F19: 86.010765 | G19: 85.557012 | H19: 89.715896 | I19: 83.012608 | J19: 98.280458 | K19: 102.80414 | L19: 95.800914 | M19: 88.815173 | N19: 99.146346 | O19: 84.535632 | P19: 98.222939 | Q19: 97.197177 | R19: 91.682526 | S19: 76.593063 | T19: 74.318735 | U19: 80.437909 | V19: 61.964884 | W19: 49.475327
B20: Natural Gas – High Efficiency | C20: 47.368911 | D20: 48.888505 | E20: 58.005085 | F20: 72.286985 | G20: 76.57086 | H20: 85.380436 | I20: 84.619745 | J20: 106.10072 | K20: 118.85855 | L20: 118.34815 | M20: 119.09799 | N20: 143.64151 | O20: 132.33971 | P20: 166.59818 | Q20: 179.51495 | R20: 186.13605 | S20: 172.63336 | T20: 187.51309 | U20: 230.4824 | V20: 202.57635 | W20: 184.52888
B21: Electric | C21: 32.949771 | D21: 30.452016 | E21: 30.571306 | F21: 34.218185 | G21: 34.973828 | H21: 32.228425 | I21: 29.493555 | J21: 32.282171 | K21: 34.270336 | L21: 36.189478 | M21: 34.68383 | N21: 35.018426 | O21: 32.846316 | P21: 38.698609 | Q21: 41.303398 | R21: 38.866897 | S21: 34.369163 | T21: 36.674609 | U21: 35.491987 | V21: 37.919876 | W21: 34.435598
B22: Heat Pump | C22: 6.272903 | D22: 6.129063 | E22: 6.473613 | F22: 7.594866 | G22: 8.093292 | H22: 7.727207 | I22: 7.24698 | J22: 8.117924 | K22: 8.750356 | L22: 9.358595 | M22: 9.021635 | N22: 9.176961 | O22: 8.661466 | P22: 10.251423 | Q22: 10.974149 | R22: 10.336222 | S22: 9.204819 | T22: 9.881614 | U22: 9.743449 | V22: 10.604689 | W22: 9.790103
B23: Other1 | C23: 4.761943 | D23: 4.420474 | E23: 4.328536 | F23: 4.913589 | G23: 4.894983 | H23: 6.421708 | I23: 7.398996 | J23: 8.378584 | K23: 9.127309 | L23: 8.197043 | M23: 8.682707 | N23: 10.351839 | O23: 11.918818 | P23: 8.439529 | Q23: 7.657762 | R23: 7.510021 | S23: 10.362144 | T23: 10.602057 | U23: 7.816384 | V23: 7.916247 | W23: 7.932062
B24: Wood | C24: 3.170268 | F24: 2.525916 | G24: 2.553871 | H24: 2.76178 | I24: 2.504901 | J24: 3.05549 | K24: 3.205282 | L24: 3.15769 | M24: 2.790147 | N24: 2.826072 | O24: 2.472899 | P24: 2.788134 | Q24: 2.78242 | R24: 2.467419 | S24: 2.305595 | T24: 2.316242 | U24: 2.079998 | V24: 1.677396 | W24: 1.468934
B25: Dual Systems
B26: Wood/Electric | C26: 16.437229 | D26: 13.694772 | E26: 13.150331 | F26: 12.692989 | G26: 12.906155 | H26: 13.079256 | I26: 12.28341 | J26: 14.253565 | K26: 15.384824 | L26: 16.032712 | M26: 15.183795 | N26: 16.518485 | O26: 15.437612 | P26: 18.551635 | Q26: 19.573572 | R26: 18.340051 | S26: 18.358006 | T26: 19.882151 | U26: 18.572905 | V26: 15.784054 | W26: 14.379021
B27: Wood/Heating Oil | C27: 8.89419 | D27: 8.100688 | E27: 9.301729 | F27: 9.368271 | G27: 9.060956 | H27: 10.587384 | I27: 9.658893 | J27: 10.109284 | K27: 9.545198 | L27: 10.23223 | M27: 10.157168 | N27: 9.193482 | O27: 8.079202 | P27: 9.331068 | Q27: 9.061592 | R27: 8.595418 | S27: 7.394041 | T27: 7.297238 | U27: 7.335409 | V27: 6.425915 | W27: 5.788741
B28: Natural Gas/Electric | C28: 1.698597 | D28: 1.603363 | E28: 1.727086 | F28: 1.991789 | G28: 1.961001 | H28: 2.012066 | I28: 1.850225 | J28: 2.170837 | K28: 2.301156 | L28: 2.214916 | M28: 2.117585 | N28: 2.410203 | O28: 2.145174 | P28: 2.594641 | Q28: 2.707079 | R28: 2.697514 | S28: 2.426134 | T28: 2.571865 | U28: 3.016677 | V28: 2.637869 | W28: 2.36032
B29: Heating Oil/Electric | C29: 0.945778 | D29: 0.90961 | E29: 1.097722 | F29: 1.155685 | G29: 1.129944 | H29: 1.335092 | I29: 1.224111 | J29: 1.268835 | K29: 1.183402 | L29: 1.287968 | M29: 1.29956 | N29: 1.133904 | O29: 0.991076 | P29: 1.137071 | Q29: 1.091081 | R29: 1.04468 | S29: 0.83789 | T29: 0.797948 | U29: 0.837883 | V29: 0.791121 | W29: 0.713613
B31: Shares (%)
B32: Heating Oil – Normal Efficiency | C32: 3.289922 | D32: 2.572253 | E32: 1.9449 | F32: 1.122623 | G32: 0.686737 | H32: 0.648062 | I32: 0.448567 | J32: 0.214797 | K32: 0.098549 | L32: 0.041819 | M32: 0 | N32: 0 | O32: 0 | P32: 0 | Q32: 0 | R32: 0 | S32: 0 | T32: 0 | U32: 0 | V32: 0 | W32: 0
B33: Heating Oil – Medium Efficiency | C33: 3.958749 | D33: 4.342926 | E33: 4.995212 | F33: 4.684333 | G33: 4.771352 | H33: 5.66963 | I33: 5.586776 | J33: 4.941099 | K33: 4.285424 | L33: 4.784337 | M33: 5.013286 | N33: 3.808472 | O33: 3.590727 | P33: 3.373773 | Q33: 2.91571 | R33: 2.677905 | S33: 2.15428 | T33: 1.739194 | U33: 1.489338 | V33: 1.3664 | W33: 1.194767
B34: Heating Oil – High Efficiency | C34: 0 | D34: 0 | E34: 0 | F34: 0 | G34: 0 | H34: 0 | I34: 0 | J34: 0 | K34: 0 | L34: 0 | M34: 0 | N34: 0 | O34: 0 | P34: 0 | Q34: 0 | R34: 0 | S34: 0 | T34: 0 | U34: 0 | V34: 0 | W34: 0
B35: Natural Gas – Normal Efficiency | C35: 37.807627 | D35: 35.601322 | E35: 32.904939 | F35: 30.569247 | G35: 27.067028 | H35: 23.702252 | I35: 20.317154 | J35: 17.51205 | K35: 14.527816 | L35: 11.17286 | M35: 8.397195 | N35: 6.067061 | O35: 3.51542 | P35: 1.374834 | Q35: 0.872713 | R35: 0.444256 | S35: 0.197751 | T35: 0.060279 | U35: 0 | V35: 0 | W35: 0
B36: Natural Gas – Medium Efficiency | C36: 19.409976 | D36: 20.59429 | E36: 21.944819 | F36: 23.510715 | G36: 24.286509 | H36: 24.988427 | I36: 25.548848 | J36: 26.759688 | K36: 27.293288 | L36: 26.751476 | M36: 26.350776 | N36: 27.125211 | O36: 26.226148 | P36: 26.235346 | Q36: 25.147673 | R36: 24.1571 | S36: 22.360269 | T36: 20.741862 | U36: 20.019433 | V36: 17.547653 | W36: 15.724838
B37: Natural Gas – High Efficiency | C37: 13.740404 | D37: 15.451914 | E37: 17.434921 | F37: 19.759372 | G37: 21.735669 | H37: 23.780878 | I37: 26.043478 | J37: 28.88898 | K37: 31.555543 | L37: 33.047574 | M37: 35.335453 | N37: 39.298535 | O37: 41.05678 | P37: 44.498374 | Q37: 46.445621 | R37: 49.044319 | S37: 50.397885 | T37: 52.333648 | U37: 57.36259 | V37: 57.367 | W37: 58.649166
B38: Electric | C38: 9.557812 | D38: 9.624797 | E38: 9.188993 | F38: 9.353411 | G38: 9.927791 | H38: 8.976532 | I38: 9.077252 | J38: 8.789752 | K38: 9.09837 | L38: 10.105561 | M38: 10.290424 | N38: 9.580607 | O38: 10.190169 | P38: 10.336398 | Q38: 10.686363 | R38: 10.240899 | S38: 10.033595 | T38: 10.235638 | U38: 8.833266 | V38: 10.738418 | W38: 10.944732
B39: Heat Pump | C39: 1.819595 | D39: 1.937178 | E39: 1.945811 | F39: 2.076028 | G39: 2.29739 | H39: 2.152247 | I39: 2.230408 | J39: 2.210339 | K39: 2.323116 | L39: 2.613297 | M39: 2.676649 | N39: 2.510703 | O39: 2.687114 | P39: 2.738155 | Q39: 2.839324 | R39: 2.723454 | S39: 2.687218 | T39: 2.757892 | U39: 2.424955 | V39: 3.003111 | W39: 3.111607
B40: Other1 | C40: 1.381307 | D40: 1.397154 | E40: 1.301053 | F40: 1.343111 | G40: 1.389507 | H40: 1.788628 | I40: 2.277194 | J40: 2.281311 | K40: 2.423193 | L40: 2.288945 | M40: 2.576092 | N40: 2.832135 | O40: 3.697668 | P40: 2.254198 | Q40: 1.981281 | R40: 1.978788 | S40: 3.025082 | T40: 2.958963 | U40: 1.945346 | V40: 2.241779 | W40: 2.521062
B41: Wood | C41: 0.919607 | D41: 0.795138 | E41: 0.741739 | F41: 0.690449 | G41: 0.724951 | H41: 0.769234 | I41: 0.770935 | J41: 0.831945 | K41: 0.850965 | L41: 0.881754 | M41: 0.827815 | N41: 0.773178 | O41: 0.767187 | P41: 0.744711 | Q41: 0.719891 | R41: 0.650131 | S41: 0.673086 | T41: 0.646448 | U41: 0.517671 | V41: 0.475017 | W41: 0.466874
B42: Dual Systems
B43: Wood/Electric | C43: 4.767983 | D43: 4.328429 | E43: 3.95267 | F43: 3.46958 | G43: 3.663586 | H43: 3.642944 | I43: 3.780474 | J43: 3.880944 | K43: 4.084489 | L43: 4.476979 | M43: 4.504915 | N43: 4.519253 | O43: 4.789331 | P43: 4.955142 | Q43: 5.064239 | R43: 4.832354 | S43: 5.359362 | T43: 5.548975 | U43: 4.622435 | V43: 4.46984 | W43: 4.570112
B44: Wood/Heating Oil | C44: 2.579957 | D44: 2.560339 | E44: 2.795874 | F44: 2.560781 | G44: 2.572074 | H44: 2.948887 | I44: 2.972724 | J44: 2.752544 | K44: 2.534138 | L44: 2.857251 | M44: 3.013553 | N44: 2.515223 | O44: 2.506474 | P44: 2.492328 | Q44: 2.344492 | R44: 2.264776 | S44: 2.158586 | T44: 2.03661 | U44: 1.825641 | V44: 1.819736 | W44: 1.839847
B45: Natural Gas/Electric | C45: 0.492716 | D45: 0.506766 | E45: 0.51912 | F45: 0.544448 | G45: 0.556656 | H45: 0.560418 | I45: 0.569445 | J45: 0.591073 | K45: 0.61093 | L45: 0.618494 | M45: 0.628271 | N45: 0.659402 | O45: 0.665514 | P45: 0.693029 | Q45: 0.700398 | R45: 0.710758 | S45: 0.708276 | T45: 0.71779 | U45: 0.750792 | V45: 0.74701 | W45: 0.750185
B46: Heating Oil/Electric | C46: 0.274344 | D46: 0.287495 | E46: 0.329949 | F46: 0.315902 | G46: 0.32075 | H46: 0.371861 | I46: 0.376745 | J46: 0.345477 | K46: 0.314179 | L46: 0.359653 | M46: 0.385569 | N46: 0.310222 | O46: 0.307469 | P46: 0.303712 | Q46: 0.282294 | R46: 0.275259 | S46: 0.24461 | T46: 0.222702 | U46: 0.208533 | V46: 0.224035 | W46: 0.226809
B48: Activity
B49: Total Floor Space (million m2) | C49: 597.715 | D49: 610.454 | E49: 624.774 | F49: 638.436 | G49: 652.623 | H49: 665.992 | I49: 679.346 | J49: 691.209 | K49: 703.358 | L49: 713.205 | M49: 723.928 | N49: 735.03 | O49: 746.765 | P49: 758.201 | Q49: 769.284 | R49: 781.726 | S49: 794.378 | T49: 806.606 | U49: 823.977 | V49: 840.774 | W49: 856.336
B51: Energy Intensity (GJ/m2) | C51: 0.576766 | D51: 0.518288 | E51: 0.532505 | F51: 0.57302 | G51: 0.539794 | H51: 0.53909 | I51: 0.47828 | J51: 0.531346 | K51: 0.535523 | L51: 0.50212 | M51: 0.465584 | N51: 0.497277 | O51: 0.43164 | P51: 0.493789 | Q51: 0.502423 | R51: 0.485498 | S51: 0.431206 | T51: 0.444211 | U51: 0.487634 | V51: 0.419998 | W51: 0.367416
...
