Workbook

Sheet Demand
A1: Appliance | B1: Pop. Index | C1: Refrigerator | D1: Freezer | E1: Dishwasher | F1: Clothes Washer | G1: Clothes Dryer | H1: Range | I1: Other Appliances
A2: 2020 | B2: 1 | C2: {=TRANSPOSE(stock!W14:W20/1000)*C11} -> 0.3592772 | D2: 0.1410247 | E2: 0.16061145 | F2: 0.21237645 | G2: 0.22007665 | H2: 0.2798109 | I2: 5.4073461
A3: 2025 | B3: 1.0754975 | C3: =C$2*$B3/$B$2 -> 0.38640173 | D3: =D$2*$B3/$B$2 -> 0.15167171 | E3: =E$2*$B3/$B$2 -> 0.17273721 | F3: =F$2*$B3/$B$2 -> 0.22841034 | G3: =G$2*$B3/$B$2 -> 0.23669189 | H3: =H$2*$B3/$B$2 -> 0.30093593 | I3: =I$2*$B3/$B$2 -> 5.8155873
A4: 2030 | B4: 1.1465282 | C4: =C$2*$B4/$B$2 -> 0.41192145 | D4: =D$2*$B4/$B$2 -> 0.1616888 | E4: =E$2*$B4/$B$2 -> 0.18414556 | F4: =F$2*$B4/$B$2 -> 0.2434956 | G4: =G$2*$B4/$B$2 -> 0.25232409 | H4: =H$2*$B4/$B$2 -> 0.3208111 | I4: =I$2*$B4/$B$2 -> 6.199675
A5: 2035 | B5: 1.2092336 | C5: =C$2*$B5/$B$2 -> 0.43445005 | D5: =D$2*$B5/$B$2 -> 0.1705318 | E5: =E$2*$B5/$B$2 -> 0.19421676 | F5: =F$2*$B5/$B$2 -> 0.25681273 | G5: =G$2*$B5/$B$2 -> 0.26612407 | H5: =H$2*$B5/$B$2 -> 0.33835673 | I5: =I$2*$B5/$B$2 -> 6.5387444
A6: 2040 | B6: 1.264116 | C6: =C$2*$B6/$B$2 -> 0.45416806 | D6: =D$2*$B6/$B$2 -> 0.17827158 | E6: =E$2*$B6/$B$2 -> 0.2030315 | F6: =F$2*$B6/$B$2 -> 0.26846847 | G6: =G$2*$B6/$B$2 -> 0.27820241 | H6: =H$2*$B6/$B$2 -> 0.35371344 | I6: =I$2*$B6/$B$2 -> 6.8355127
A7: 2045 | B7: 1.3130498 | C7: =C$2*$B7/$B$2 -> 0.47174885 | D7: =D$2*$B7/$B$2 -> 0.18517245 | E7: =E$2*$B7/$B$2 -> 0.21089083 | F7: =F$2*$B7/$B$2 -> 0.27886085 | G7: =G$2*$B7/$B$2 -> 0.2889716 | H7: =H$2*$B7/$B$2 -> 0.36740564 | I7: =I$2*$B7/$B$2 -> 7.1001146
A8: 2050 | B8: 1.3579363 | C8: =C$2*$B8/$B$2 -> 0.48787556 | D8: =D$2*$B8/$B$2 -> 0.19150256 | E8: =E$2*$B8/$B$2 -> 0.21810012 | F8: =F$2*$B8/$B$2 -> 0.28839369 | G8: =G$2*$B8/$B$2 -> 0.29885007 | H8: =H$2*$B8/$B$2 -> 0.37996538 | I8: =I$2*$B8/$B$2 -> 7.3428316
A9: Units | C9: Munit.yr | D9: Munit.yr | E9: Munit.yr | F9: Munit.yr | G9: Munit.yr | H9: Munit.yr | I9: Munit.yr
A11: Arbitrary annual capacity factor | C11: 0.05

Sheet Existing capacities
A1: Technology | B1: Model tech | C1: Existing capacity (Munits) 2020 | D1: 2023 | E1: Lifetimes
A2: Refrigerator | B2: R_APP_REF_MEF | C2: =stock!W14/1000 -> 7.185544 | D2: =C2*$D$12/$C$12 -> 7.500797 | E2: 15
A3: Freezer | B3: R_APP_FRZ_MEF | C3: =stock!W15/1000 -> 2.820494 | D3: =C3*$D$12/$C$12 -> 2.9442382 | E3: 21
A4: Dishwasher | B4: R_APP_DSH_MEF | C4: =stock!W16/1000 -> 3.212229 | D4: =C4*$D$12/$C$12 -> 3.3531598 | E4: 15
A5: Clothes Washer | B5: R_APP_CWSH_MEF | C5: =stock!W17/1000 -> 4.247529 | D5: =C5*$D$12/$C$12 -> 4.4338818 | E5: 12
A6: Clothes Dryer (electric) | B6: R_APP_CDRY_ELC_MEF | C6: =stock!W18/1000 -> 4.401533 | D6: =C6*$D$12/$C$12 -> 4.5946424 | E6: 13
A7: Clothes Dryer (natural gas) | B7: R_APP_CDRY_NGS_MEF | C7: =stock!W50/1000 -> 0.120426 | D7: =C7*$D$12/$C$12 -> 0.12570948 | E7: 13
A8: Range (electric) | B8: R_APP_COOK_RNG_ELC_MEF | C8: =stock!W19/1000 -> 5.596218 | D8: =C8*$D$12/$C$12 -> 5.8417421 | E8: 17
A9: Range (natural gas) | B9: R_APP_COOK_RNG_NGS_MEF | C9: =stock!W51/1000 -> 0.794663 | D9: =C9*$D$12/$C$12 -> 0.82952742 | E9: 15
A10: Other Appliances1 | B10: R_APP_OTH_APP | C10: =stock!W20/1000 -> 108.14692 | D10: =C10*$D$12/$C$12 -> 112.89168 | E10: 0 | F10: (inf)
A12: Population index | C12: 1 | D12: 1.0438732

Sheet Munit.yr per PJ
A1: Appliance Munits/PJ (bigger better) | B1: Cost invest | C1: Cost fixed | D1: Life | E1: 2000 | F1: 2005 | G1: 2010 | H1: 2015 | I1: 2018 | J1: 2025 | K1: 2030 | L1: 2035 | M1: 2040 | N1: 2045 | O1: 2050 | P1: These are not vintages. They are periods of existing capacity
A2: Refrigerator | E2: =$I2 -> 0.042620886 | F2: =$I2 -> 0.042620886 | G2: =$I2 -> 0.042620886 | H2: =$I2 -> 0.042620886 | I2: =stock!U14*Demand!$C$11/1000/'secondary energy'!U15 -> 0.042620886 | J2: =$I2 -> 0.042620886 | K2: =$I2 -> 0.042620886 | L2: =$I2 -> 0.042620886 | M2: =$I2 -> 0.042620886 | N2: =$I2 -> 0.042620886 | O2: =$I2 -> 0.042620886
A3: Freezer | E3: =$I3 -> 0.052328969 | F3: =$I3 -> 0.052328969 | G3: =$I3 -> 0.052328969 | H3: =$I3 -> 0.052328969 | I3: =stock!U15*Demand!$C$11/1000/'secondary energy'!U16 -> 0.052328969 | J3: =$I3 -> 0.052328969 | K3: =$I3 -> 0.052328969 | L3: =$I3 -> 0.052328969 | M3: =$I3 -> 0.052328969 | N3: =$I3 -> 0.052328969 | O3: =$I3 -> 0.052328969
A4: Dishwasher | E4: =$I4 -> 0.24048269 | F4: =$I4 -> 0.24048269 | G4: =$I4 -> 0.24048269 | H4: =$I4 -> 0.24048269 | I4: =stock!U16*Demand!$C$11/1000/'secondary energy'!U17 -> 0.24048269 | J4: =$I4 -> 0.24048269 | K4: =$I4 -> 0.24048269 | L4: =$I4 -> 0.24048269 | M4: =$I4 -> 0.24048269 | N4: =$I4 -> 0.24048269 | O4: =$I4 -> 0.24048269
A5: Clothes Washer | E5: =$I5 -> 0.44118481 | F5: =$I5 -> 0.44118481 | G5: =$I5 -> 0.44118481 | H5: =$I5 -> 0.44118481 | I5: =stock!U17*Demand!$C$11/1000/'secondary energy'!U18 -> 0.44118481 | J5: =$I5 -> 0.44118481 | K5: =$I5 -> 0.44118481 | L5: =$I5 -> 0.44118481 | M5: =$I5 -> 0.44118481 | N5: =$I5 -> 0.44118481 | O5: =$I5 -> 0.44118481
A6: Clothes Dryer | E6: =$I6 -> 0.02117285 | F6: =$I6 -> 0.02117285 | G6: =$I6 -> 0.02117285 | H6: =$I6 -> 0.02117285 | I6: =stock!U18*Demand!$C$11/1000/'secondary energy'!U19 -> 0.02117285 | J6: =$I6 -> 0.02117285 | K6: =$I6 -> 0.02117285 | L6: =$I6 -> 0.02117285 | M6: =$I6 -> 0.02117285 | N6: =$I6 -> 0.02117285 | O6: =$I6 -> 0.02117285
A7: Range | E7: =$I7 -> 0.023948001 | F7: =$I7 -> 0.023948001 | G7: =$I7 -> 0.023948001 | H7: =$I7 -> 0.023948001 | I7: =stock!U19*Demand!$C$11/1000/'secondary energy'!U20 -> 0.023948001 | J7: =$I7 -> 0.023948001 | K7: =$I7 -> 0.023948001 | L7: =$I7 -> 0.023948001 | M7: =$I7 -> 0.023948001 | N7: =$I7 -> 0.023948001 | O7: =$I7 -> 0.023948001
A8: Other Appliances | E8: =$I8 -> 0.18562273 | F8: =$I8 -> 0.18562273 | G8: =$I8 -> 0.18562273 | H8: =$I8 -> 0.18562273 | I8: =stock!U20*Demand!$C$11/1000/'secondary energy'!U21 -> 0.18562273 | J8: =$I8 -> 0.18562273 | K8: =$I8 -> 0.18562273 | L8: =$I8 -> 0.18562273 | M8: =$I8 -> 0.18562273 | N8: =$I8 -> 0.18562273 | O8: =$I8 -> 0.18562273
A10: Technology
A11: R_APP_REF_MEF | E11: {=E2:O2} -> 0.042620886 | F11: 0.042620886 | G11: 0.042620886 | H11: 0.042620886 | I11: 0.042620886 | J11: 0.042620886 | K11: 0.042620886 | L11: 0.042620886 | M11: 0.042620886 | N11: 0.042620886 | O11: 0.042620886
A12: R_APP_REF_HEF | E12: {=E2:O2} -> 0.042620886 | F12: 0.042620886 | G12: 0.042620886 | H12: 0.042620886 | I12: 0.042620886 | J12: 0.042620886 | K12: 0.042620886 | L12: 0.042620886 | M12: 0.042620886 | N12: 0.042620886 | O12: 0.042620886
A13: R_APP_FRZ_MEF | E13: {=E3:O3} -> 0.052328969 | F13: 0.052328969 | G13: 0.052328969 | H13: 0.052328969 | I13: 0.052328969 | J13: 0.052328969 | K13: 0.052328969 | L13: 0.052328969 | M13: 0.052328969 | N13: 0.052328969 | O13: 0.052328969
A14: R_APP_FRZ_HEF | E14: {=E3:O3} -> 0.052328969 | F14: 0.052328969 | G14: 0.052328969 | H14: 0.052328969 | I14: 0.052328969 | J14: 0.052328969 | K14: 0.052328969 | L14: 0.052328969 | M14: 0.052328969 | N14: 0.052328969 | O14: 0.052328969
A15: R_APP_DSH_MEF | E15: {=E4:O4} -> 0.24048269 | F15: 0.24048269 | G15: 0.24048269 | H15: 0.24048269 | I15: 0.24048269 | J15: 0.24048269 | K15: 0.24048269 | L15: 0.24048269 | M15: 0.24048269 | N15: 0.24048269 | O15: 0.24048269
A16: R_APP_DSH_HEF | E16: {=E4:O4} -> 0.24048269 | F16: 0.24048269 | G16: 0.24048269 | H16: 0.24048269 | I16: 0.24048269 | J16: 0.24048269 | K16: 0.24048269 | L16: 0.24048269 | M16: 0.24048269 | N16: 0.24048269 | O16: 0.24048269
A17: R_APP_CWSH_MEF | E17: {=E5:O5} -> 0.44118481 | F17: 0.44118481 | G17: 0.44118481 | H17: 0.44118481 | I17: 0.44118481 | J17: 0.44118481 | K17: 0.44118481 | L17: 0.44118481 | M17: 0.44118481 | N17: 0.44118481 | O17: 0.44118481
A18: R_APP_CWSH_HEF | E18: {=E5:O5} -> 0.44118481 | F18: 0.44118481 | G18: 0.44118481 | H18: 0.44118481 | I18: 0.44118481 | J18: 0.44118481 | K18: 0.44118481 | L18: 0.44118481 | M18: 0.44118481 | N18: 0.44118481 | O18: 0.44118481
A19: R_APP_CDRY_EXS | E19: {=E6:O6} -> 0.02117285 | F19: 0.02117285 | G19: 0.02117285 | H19: 0.02117285 | I19: 0.02117285 | J19: 0.02117285 | K19: 0.02117285 | L19: 0.02117285 | M19: 0.02117285 | N19: 0.02117285 | O19: 0.02117285
A20: R_APP_CDRY_ELC_MEF | E20: {=E6:O6} -> 0.02117285 | F20: 0.02117285 | G20: 0.02117285 | H20: 0.02117285 | I20: 0.02117285 | J20: 0.02117285 | K20: 0.02117285 | L20: 0.02117285 | M20: 0.02117285 | N20: 0.02117285 | O20: 0.02117285
A21: R_APP_CDRY_ELC_HEF | E21: {=E6:O6} -> 0.02117285 | F21: 0.02117285 | G21: 0.02117285 | H21: 0.02117285 | I21: 0.02117285 | J21: 0.02117285 | K21: 0.02117285 | L21: 0.02117285 | M21: 0.02117285 | N21: 0.02117285 | O21: 0.02117285
A22: R_APP_CDRY_LPG_MEF | E22: {=E6:O6} -> 0.02117285 | F22: 0.02117285 | G22: 0.02117285 | H22: 0.02117285 | I22: 0.02117285 | J22: 0.02117285 | K22: 0.02117285 | L22: 0.02117285 | M22: 0.02117285 | N22: 0.02117285 | O22: 0.02117285
A23: R_APP_CDRY_LPG_HEF | E23: {=E6:O6} -> 0.02117285 | F23: 0.02117285 | G23: 0.02117285 | H23: 0.02117285 | I23: 0.02117285 | J23: 0.02117285 | K23: 0.02117285 | L23: 0.02117285 | M23: 0.02117285 | N23: 0.02117285 | O23: 0.02117285
A24: R_APP_CDRY_NGS_MEF | E24: {=E6:O6} -> 0.02117285 | F24: 0.02117285 | G24: 0.02117285 | H24: 0.02117285 | I24: 0.02117285 | J24: 0.02117285 | K24: 0.02117285 | L24: 0.02117285 | M24: 0.02117285 | N24: 0.02117285 | O24: 0.02117285
A25: R_APP_CDRY_NGS_HEF | E25: {=E6:O6} -> 0.02117285 | F25: 0.02117285 | G25: 0.02117285 | H25: 0.02117285 | I25: 0.02117285 | J25: 0.02117285 | K25: 0.02117285 | L25: 0.02117285 | M25: 0.02117285 | N25: 0.02117285 | O25: 0.02117285
A26: R_APP_COOK_RNG_EXS | E26: {=E7:O7} -> 0.023948001 | F26: 0.023948001 | G26: 0.023948001 | H26: 0.023948001 | I26: 0.023948001 | J26: 0.023948001 | K26: 0.023948001 | L26: 0.023948001 | M26: 0.023948001 | N26: 0.023948001 | O26: 0.023948001
A27: R_APP_COOK_RNG_ELC_MEF | E27: {=E7:O7} -> 0.023948001 | F27: 0.023948001 | G27: 0.023948001 | H27: 0.023948001 | I27: 0.023948001 | J27: 0.023948001 | K27: 0.023948001 | L27: 0.023948001 | M27: 0.023948001 | N27: 0.023948001 | O27: 0.023948001
A28: R_APP_COOK_RNG_ELC_HEF | E28: {=E7:O7} -> 0.023948001 | F28: 0.023948001 | G28: 0.023948001 | H28: 0.023948001 | I28: 0.023948001 | J28: 0.023948001 | K28: 0.023948001 | L28: 0.023948001 | M28: 0.023948001 | N28: 0.023948001 | O28: 0.023948001
A29: R_APP_COOK_RNG_LPG_MEF | E29: {=E7:O7} -> 0.023948001 | F29: 0.023948001 | G29: 0.023948001 | H29: 0.023948001 | I29: 0.023948001 | J29: 0.023948001 | K29: 0.023948001 | L29: 0.023948001 | M29: 0.023948001 | N29: 0.023948001 | O29: 0.023948001
A30: R_APP_COOK_RNG_LPG_HEF | E30: {=E7:O7} -> 0.023948001 | F30: 0.023948001 | G30: 0.023948001 | H30: 0.023948001 | I30: 0.023948001 | J30: 0.023948001 | K30: 0.023948001 | L30: 0.023948001 | M30: 0.023948001 | N30: 0.023948001 | O30: 0.023948001
A31: R_APP_COOK_RNG_NGS_MEF | E31: {=E7:O7} -> 0.023948001 | F31: 0.023948001 | G31: 0.023948001 | H31: 0.023948001 | I31: 0.023948001 | J31: 0.023948001 | K31: 0.023948001 | L31: 0.023948001 | M31: 0.023948001 | N31: 0.023948001 | O31: 0.023948001
A32: R_APP_COOK_RNG_NGS_HEF | E32: {=E7:O7} -> 0.023948001 | F32: 0.023948001 | G32: 0.023948001 | H32: 0.023948001 | I32: 0.023948001 | J32: 0.023948001 | K32: 0.023948001 | L32: 0.023948001 | M32: 0.023948001 | N32: 0.023948001 | O32: 0.023948001
A33: R_APP_OTH_APP | E33: {=E8:O8} -> 0.18562273 | F33: 0.18562273 | G33: 0.18562273 | H33: 0.18562273 | I33: 0.18562273 | J33: 0.18562273 | K33: 0.18562273 | L33: 0.18562273 | M33: 0.18562273 | N33: 0.18562273 | O33: 0.18562273
A35: Adjusted for relative efficiency | E35: 2000 | F35: 2005 | G35: 2010 | H35: 2015 | I35: 2020 | J35: 2025 | K35: 2030 | L35: 2035 | M35: 2040 | N35: 2045 | O35: 2050
A36: R_APP_REF_MEF | B36: 750 | C36: 10 | D36: 15 | E36: =E11*'Rel. eff.'!B29 -> 0.033380811 | F36: =F11*'Rel. eff.'!C29 -> 0.033380811 | G36: =G11*'Rel. eff.'!D29 -> 0.033380811 | H36: =H11*'Rel. eff.'!E29 -> 0.033380811 | I36: =I11*'Rel. eff.'!F29 -> 0.042620886 | J36: =J11*'Rel. eff.'!H29 -> 0.042620886 | K36: =K11*'Rel. eff.'!I29 -> 0.042620886 | L36: =L11*'Rel. eff.'!J29 -> 0.042620886 | M36: =M11*'Rel. eff.'!K29 -> 0.042620886 | N36: =N11*'Rel. eff.'!L29 -> 0.042620886 | O36: =O11*'Rel. eff.'!M29 -> 0.042620886 | R36: {=TRANSPOSE(A36:O58)} -> R_APP_REF_MEF | S36: R_APP_REF_HEF | T36: R_APP_FRZ_MEF | U36: R_APP_FRZ_HEF | V36: R_APP_DSH_MEF | W36: R_APP_DSH_HEF | X36: R_APP_CWSH_MEF | Y36: R_APP_CWSH_HEF | Z36: 0 | AA36: R_APP_CDRY_ELC_MEF | AB36: R_APP_CDRY_ELC_HEF | AC36: R_APP_CDRY_LPG_MEF | AD36: R_APP_CDRY_LPG_HEF | AE36: R_APP_CDRY_NGS_MEF | AF36: R_APP_CDRY_NGS_HEF | AG36: 0 | AH36: R_APP_COOK_RNG_ELC_MEF | AI36: R_APP_COOK_RNG_ELC_HEF | AJ36: R_APP_COOK_RNG_LPG_MEF | AK36: R_APP_COOK_RNG_LPG_HEF | AL36: R_APP_COOK_RNG_NGS_MEF | AM36: R_APP_COOK_RNG_NGS_HEF | AN36: R_APP_OTH_APP
A37: R_APP_REF_HEF | B37: 760 | C37: 10 | D37: 15 | J37: =J12*'Rel. eff.'!H30 -> 0.047740155 | K37: =K12*'Rel. eff.'!I30 -> 0.047740155 | L37: =L12*'Rel. eff.'!J30 -> 0.047740155 | M37: =M12*'Rel. eff.'!K30 -> 0.047740155 | N37: =N12*'Rel. eff.'!L30 -> 0.047740155 | O37: =O12*'Rel. eff.'!M30 -> 0.047740155 | Q37: {=TRANSPOSE(B1:O1)} -> Cost invest | R37: 750 | S37: 760 | T37: 680 | U37: 690 | V37: 340 | W37: 500 | X37: 520 | Y37: 725 | Z37: 0 | AA37: 710 | AB37: 1110 | AC37: 670 | AD37: 870 | AE37: 670 | AF37: 870 | AG37: 0 | AH37: 770 | AI37: 1050 | AJ37: 920 | AK37: 1000 | AL37: 920 | AM37: 1000 | AN37: 0
A38: R_APP_FRZ_MEF | B38: 680 | C38: 10 | D38: 21 | E38: =E13*'Rel. eff.'!B31 -> 0.0431714 | F38: =F13*'Rel. eff.'!C31 -> 0.0431714 | G38: =G13*'Rel. eff.'!D31 -> 0.0431714 | H38: =H13*'Rel. eff.'!E31 -> 0.0431714 | I38: =I13*'Rel. eff.'!F31 -> 0.052328969 | J38: =J13*'Rel. eff.'!H31 -> 0.052328969 | K38: =K13*'Rel. eff.'!I31 -> 0.052328969 | L38: =L13*'Rel. eff.'!J31 -> 0.052328969 | M38: =M13*'Rel. eff.'!K31 -> 0.052328969 | N38: =N13*'Rel. eff.'!L31 -> 0.052328969 | O38: =O13*'Rel. eff.'!M31 -> 0.052328969 | Q38: Cost fixed | R38: 10 | S38: 10 | T38: 10 | U38: 10 | V38: 0 | W38: 0 | X38: 15 | Y38: 15 | Z38: 0 | AA38: 0 | AB38: 0 | AC38: 0 | AD38: 0 | AE38: 0 | AF38: 0 | AG38: 0 | AH38: 0 | AI38: 0 | AJ38: 0 | AK38: 0 | AL38: 0 | AM38: 0 | AN38: 0
A39: R_APP_FRZ_HEF | B39: 690 | C39: 10 | D39: 21 | J39: =J14*'Rel. eff.'!H32 -> 0.054152279 | K39: =K14*'Rel. eff.'!I32 -> 0.054152279 | L39: =L14*'Rel. eff.'!J32 -> 0.054152279 | M39: =M14*'Rel. eff.'!K32 -> 0.054152279 | N39: =N14*'Rel. eff.'!L32 -> 0.054152279 | O39: =O14*'Rel. eff.'!M32 -> 0.054152279 | Q39: Life | R39: 15 | S39: 15 | T39: 21 | U39: 21 | V39: 15 | W39: 15 | X39: 12 | Y39: 12 | Z39: 0 | AA39: 13 | AB39: 13 | AC39: 13 | AD39: 13 | AE39: 13 | AF39: 13 | AG39: 0 | AH39: 17 | AI39: 17 | AJ39: 15 | AK39: 15 | AL39: 15 | AM39: 15 | AN39: 100
A40: R_APP_DSH_MEF | B40: 340 | D40: 15 | E40: =E15*'Rel. eff.'!B33 -> 0.2201028 | F40: =F15*'Rel. eff.'!C33 -> 0.2201028 | G40: =G15*'Rel. eff.'!D33 -> 0.2201028 | H40: =H15*'Rel. eff.'!E33 -> 0.2201028 | I40: =I15*'Rel. eff.'!F33 -> 0.24048269 | J40: =J15*'Rel. eff.'!H33 -> 0.25093846 | K40: =K15*'Rel. eff.'!I33 -> 0.27054302 | L40: =L15*'Rel. eff.'!J33 -> 0.27054302 | M40: =M15*'Rel. eff.'!K33 -> 0.27054302 | N40: =N15*'Rel. eff.'!L33 -> 0.27054302 | O40: =O15*'Rel. eff.'!M33 -> 0.27054302 | Q40: 2000 | R40: 0.033380811 | S40: 0 | T40: 0.0431714 | U40: 0 | V40: 0.2201028 | W40: 0 | X40: 0.43275453 | Y40: 0 | Z40: 0 | AA40: 0.020442637 | AB40: 0 | AC40: 0.018107962 | AD40: 0 | AE40: 0.018107962 | AF40: 0 | AG40: 0 | AH40: 0.026163647 | AI40: 0 | AJ40: 0.014691767 | AK40: 0 | AL40: 0.014691767 | AM40: 0 | AN40: 0.18562273
A41: R_APP_DSH_HEF | B41: 500 | D41: 15 | J41: =J16*'Rel. eff.'!H34 -> 0.28857922 | K41: =K16*'Rel. eff.'!I34 -> 0.28857922 | L41: =L16*'Rel. eff.'!J34 -> 0.28857922 | M41: =M16*'Rel. eff.'!K34 -> 0.28857922 | N41: =N16*'Rel. eff.'!L34 -> 0.28857922 | O41: =O16*'Rel. eff.'!M34 -> 0.28857922 | Q41: 2005 | R41: 0.033380811 | S41: 0 | T41: 0.0431714 | U41: 0 | V41: 0.2201028 | W41: 0 | X41: 0.43275453 | Y41: 0 | Z41: 0 | AA41: 0.020442637 | AB41: 0 | AC41: 0.018107962 | AD41: 0 | AE41: 0.018107962 | AF41: 0 | AG41: 0 | AH41: 0.026163647 | AI41: 0 | AJ41: 0.014691767 | AK41: 0 | AL41: 0.014691767 | AM41: 0 | AN41: 0.18562273
A42: R_APP_CWSH_MEF | B42: 520 | C42: 15 | D42: 12 | E42: =E17*'Rel. eff.'!B35 -> 0.43275453 | F42: =F17*'Rel. eff.'!C35 -> 0.43275453 | G42: =G17*'Rel. eff.'!D35 -> 0.43275453 | H42: =H17*'Rel. eff.'!E35 -> 0.43275453 | I42: =I17*'Rel. eff.'!F35 -> 0.44118481 | J42: =J17*'Rel. eff.'!H35 -> 0.44118481 | K42: =K17*'Rel. eff.'!I35 -> 0.44118481 | L42: =L17*'Rel. eff.'!J35 -> 0.44118481 | M42: =M17*'Rel. eff.'!K35 -> 0.44118481 | N42: =N17*'Rel. eff.'!L35 -> 0.44118481 | O42: =O17*'Rel. eff.'!M35 -> 0.44118481 | Q42: 2010 | R42: 0.033380811 | S42: 0 | T42: 0.0431714 | U42: 0 | V42: 0.2201028 | W42: 0 | X42: 0.43275453 | Y42: 0 | Z42: 0 | AA42: 0.020442637 | AB42: 0 | AC42: 0.018107962 | AD42: 0 | AE42: 0.018107962 | AF42: 0 | AG42: 0 | AH42: 0.026163647 | AI42: 0 | AJ42: 0.014691767 | AK42: 0 | AL42: 0.014691767 | AM42: 0 | AN42: 0.18562273
...

Sheet Rel. eff.
A1: Absolute efficiency / energy consumption (AEO updated assumptions 2023)
A2: Appliance | B2: 2000 | C2: 2005 | D2: 2010 | E2: 2015 | F2: 2020 | G2: 2022 (EXS) | H2: 2025 | I2: 2030 | J2: 2035 | K2: 2040 | L2: 2045 | M2: 2050 | N2: units
A3: R_APP_REF_MEF | B3: 512 | C3: 512 | D3: 512 | E3: 512 | F3: 401 | G3: 401 | H3: 401 | I3: 401 | J3: 401 | K3: 401 | L3: 401 | M3: 401 | N3: kWh/y
A4: R_APP_REF_HEF | G4: 358 | H4: 358 | I4: 358 | J4: 358 | K4: 358 | L4: 358 | M4: 358 | N4: kWh/y
A5: R_APP_FRZ_MEF | B5: 360 | C5: 360 | D5: 360 | E5: 360 | F5: 297 | G5: 297 | H5: 297 | I5: 297 | J5: 297 | K5: 297 | L5: 297 | M5: 297 | N5: kWh/y
A6: R_APP_FRZ_HEF | G6: 287 | H6: 287 | I6: 287 | J6: 287 | K6: 287 | L6: 287 | M6: 287 | N6: kWh/y
A7: R_APP_DSH_MEF | B7: 295 | C7: 295 | D7: 295 | E7: 295 | F7: 270 | G7: 270 | H7: =(I7-G7)*3/8+G7 -> 258.75 | I7: 240 | J7: 240 | K7: 240 | L7: 240 | M7: 240 | N7: kWh/y
A8: R_APP_DSH_HEF | G8: 225 | H8: 225 | I8: 225 | J8: 225 | K8: 225 | L8: 225 | M8: 225 | N8: kWh/y
A9: R_APP_CWSH_MEF | B9: 1.54 | C9: 1.54 | D9: 1.54 | E9: 1.54 | F9: 1.57 | G9: 1.57 | H9: 1.57 | I9: 1.57 | J9: 1.57 | K9: 1.57 | L9: 1.57 | M9: 1.57 | N9: ft3cycle/kWh
A10: R_APP_CWSH_HEF | G10: 2.76 | H10: 2.76 | I10: 2.76 | J10: 2.76 | K10: 2.76 | L10: 2.76 | M10: 2.76 | N10: ft3cycle/kWh
A11: R_APP_CDRY_EXS | B11: =(stock!$W$36*'Rel. eff.'!B12+stock!$W$50*'Rel. eff.'!B14)/stock!$W$18 -> 3.5787824 | C11: =(stock!$W$36*'Rel. eff.'!C12+stock!$W$50*'Rel. eff.'!C14)/stock!$W$18 -> 3.5787824 | D11: =(stock!$W$36*'Rel. eff.'!D12+stock!$W$50*'Rel. eff.'!D14)/stock!$W$18 -> 3.5787824 | E11: =(stock!$W$36*'Rel. eff.'!E12+stock!$W$50*'Rel. eff.'!E14)/stock!$W$18 -> 3.5787824 | F11: =(stock!$W$36*'Rel. eff.'!F12+stock!$W$50*'Rel. eff.'!F14)/stock!$W$18 -> 3.7182352 | G11: =(stock!$W$36*'Rel. eff.'!G12+stock!$W$50*'Rel. eff.'!G14)/stock!$W$18 -> 3.7182352 | H11: =(stock!$W$36*'Rel. eff.'!H12+stock!$W$50*'Rel. eff.'!H14)/stock!$W$18 -> 3.7182352 | I11: =(stock!$W$36*'Rel. eff.'!I12+stock!$W$50*'Rel. eff.'!I14)/stock!$W$18 -> 3.7182352 | ... M11: =(stock!$W$36*'Rel. eff.'!M12+stock!$W$50*'Rel. eff.'!M14)/stock!$W$18 -> 3.7182352 | N11: lb/kWh
A12: R_APP_CDRY_ELC_MEF | B12: 3.59 | C12: 3.59 | D12: 3.59 | E12: 3.59 | F12: 3.73 | G12: 3.73 | H12: 3.73 | I12: 3.73 | J12: 3.73 | K12: 3.73 | L12: 3.73 | M12: 3.73 | N12: lb/kWh
A13: R_APP_CDRY_ELC_HEF | G13: 3.93 | H13: 3.93 | I13: 3.93 | J13: 3.93 | K13: 3.93 | L13: 3.93 | M13: 3.93 | N13: lb/kWh
A14: R_APP_CDRY_LPG_MEF | B14: 3.18 | C14: 3.18 | D14: 3.18 | E14: 3.18 | F14: 3.3 | G14: 3.3 | H14: 3.3 | I14: 3.3 | J14: 3.3 | K14: 3.3 | L14: 3.3 | M14: 3.3 | N14: lb/kWh
A15: R_APP_CDRY_LPG_HEF | G15: 3.48 | H15: 3.48 | I15: 3.48 | J15: 3.48 | K15: 3.48 | L15: 3.48 | M15: 3.48 | N15: lb/kWh
A16: R_APP_CDRY_NGS_MEF | B16: 3.18 | C16: 3.18 | D16: 3.18 | E16: 3.18 | F16: 3.3 | G16: 3.3 | H16: 3.3 | I16: 3.3 | J16: 3.3 | K16: 3.3 | L16: 3.3 | M16: 3.3 | N16: lb/kWh
A17: R_APP_CDRY_NGS_HEF | G17: 3.48 | H17: 3.48 | I17: 3.48 | J17: 3.48 | K17: 3.48 | L17: 3.48 | M17: 3.48 | N17: lb/kWh
A18: R_APP_COOK_RNG_EXS | B18: =(stock!$W$37*'Rel. eff.'!B19+0.293071*stock!$W$51*'Rel. eff.'!B21)/stock!$W$19 -> 566.54833 | C18: =(stock!$W$37*'Rel. eff.'!C19+0.293071*stock!$W$51*'Rel. eff.'!C21)/stock!$W$19 -> 566.54833 | D18: =(stock!$W$37*'Rel. eff.'!D19+0.293071*stock!$W$51*'Rel. eff.'!D21)/stock!$W$19 -> 566.54833 | E18: =(stock!$W$37*'Rel. eff.'!E19+0.293071*stock!$W$51*'Rel. eff.'!E21)/stock!$W$19 -> 566.54833 | F18: =(stock!$W$37*'Rel. eff.'!F19+0.293071*stock!$W$51*'Rel. eff.'!F21)/stock!$W$19 -> 557.18471 | G18: =(stock!$W$37*'Rel. eff.'!G19+0.293071*stock!$W$51*'Rel. eff.'!G21)/stock!$W$19 -> 557.18471 | H18: =(stock!$W$37*'Rel. eff.'!H19+0.293071*stock!$W$51*'Rel. eff.'!H21)/stock!$W$19 -> 557.18471 | I18: =(stock!$W$37*'Rel. eff.'!I19+0.293071*stock!$W$51*'Rel. eff.'!I21)/stock!$W$19 -> 557.18471 | ... M18: =(stock!$W$37*'Rel. eff.'!M19+0.293071*stock!$W$51*'Rel. eff.'!M21)/stock!$W$19 -> 557.18471 | N18: kWh/y
A19: R_APP_COOK_RNG_ELC_MEF | B19: 510 | C19: 510 | D19: 510 | E19: 510 | F19: 510 | G19: 510 | H19: 510 | I19: 510 | J19: 510 | K19: 510 | L19: 510 | M19: 510 | N19: kWh/y
A20: R_APP_COOK_RNG_ELC_HEF | G20: 397 | H20: 397 | I20: 397 | J20: 397 | K20: 397 | L20: 397 | M20: 397 | N20: kWh/y
A21: R_APP_COOK_RNG_LPG_MEF | B21: 3099 | C21: 3099 | D21: 3099 | E21: 3099 | F21: 2874 | G21: 2874 | H21: 2874 | I21: 2874 | J21: 2874 | K21: 2874 | L21: 2874 | M21: 2874 | N21: kBTU/y
A22: R_APP_COOK_RNG_LPG_HEF | G22: 2561 | H22: 2561 | I22: 2561 | J22: 2561 | K22: 2561 | L22: 2561 | M22: 2561 | N22: kBTU/y
A23: R_APP_COOK_RNG_NGS_MEF | B23: 3099 | C23: 3099 | D23: 3099 | E23: 3099 | F23: 2874 | G23: 2874 | H23: 2874 | I23: 2874 | J23: 2874 | K23: 2874 | L23: 2874 | M23: 2874 | N23: kBTU/y
A24: R_APP_COOK_RNG_NGS_HEF | G24: 2561 | H24: 2561 | I24: 2561 | J24: 2561 | K24: 2561 | L24: 2561 | M24: 2561 | N24: kBTU/y
A25: R_APP_OTH_APP
A27: Relative to base year and tech
A28: Appliance | B28: 2000 | C28: 2005 | D28: 2010 | E28: 2015 | F28: 2020 | G28: 2022 (EXS) | H28: 2025 | I28: 2030 | J28: 2035 | K28: 2040 | L28: 2045 | M28: 2050 | N28: units
A29: R_APP_REF_MEF | B29: =1/(B3/$G3) -> 0.78320312 | C29: =1/(C3/$G3) -> 0.78320312 | D29: =1/(D3/$G3) -> 0.78320312 | E29: =1/(E3/$G3) -> 0.78320312 | F29: =1/(F3/$G3) -> 1 | G29: =1/(G3/$G3) -> 1 | H29: =1/(H3/$G3) -> 1 | I29: =1/(I3/$G3) -> 1 | ... M29: =1/(M3/$G3) -> 1 | N29: Munit.yr/PJ
A30: R_APP_REF_HEF | H30: =1/(H4/$G3) -> 1.1201117 | I30: =1/(I4/$G3) -> 1.1201117 | J30: =1/(J4/$G3) -> 1.1201117 | K30: =1/(K4/$G3) -> 1.1201117 | L30: =1/(L4/$G3) -> 1.1201117 | M30: =1/(M4/$G3) -> 1.1201117 | N30: Munit.yr/PJ
A31: R_APP_FRZ_MEF | B31: =1/(B5/$G5) -> 0.825 | C31: =1/(C5/$G5) -> 0.825 | D31: =1/(D5/$G5) -> 0.825 | E31: =1/(E5/$G5) -> 0.825 | F31: =1/(F5/$G5) -> 1 | G31: =1/(G5/$G5) -> 1 | H31: =1/(H5/$G5) -> 1 | I31: =1/(I5/$G5) -> 1 | ... M31: =1/(M5/$G5) -> 1 | N31: Munit.yr/PJ
A32: R_APP_FRZ_HEF | H32: =1/(H6/$G5) -> 1.0348432 | I32: =1/(I6/$G5) -> 1.0348432 | J32: =1/(J6/$G5) -> 1.0348432 | K32: =1/(K6/$G5) -> 1.0348432 | L32: =1/(L6/$G5) -> 1.0348432 | M32: =1/(M6/$G5) -> 1.0348432 | N32: Munit.yr/PJ
A33: R_APP_DSH_MEF | B33: =1/(B7/$G7) -> 0.91525424 | C33: =1/(C7/$G7) -> 0.91525424 | D33: =1/(D7/$G7) -> 0.91525424 | E33: =1/(E7/$G7) -> 0.91525424 | F33: =1/(F7/$G7) -> 1 | G33: =1/(G7/$G7) -> 1 | H33: =1/(H7/$G7) -> 1.0434783 | I33: =1/(I7/$G7) -> 1.125 | ... M33: =1/(M7/$G7) -> 1.125 | N33: Munit.yr/PJ
A34: R_APP_DSH_HEF | H34: =1/(H8/$G7) -> 1.2 | I34: =1/(I8/$G7) -> 1.2 | J34: =1/(J8/$G7) -> 1.2 | K34: =1/(K8/$G7) -> 1.2 | L34: =1/(L8/$G7) -> 1.2 | M34: =1/(M8/$G7) -> 1.2 | N34: Munit.yr/PJ
A35: R_APP_CWSH_MEF | B35: =B9/$G9 -> 0.98089172 | C35: =C9/$G9 -> 0.98089172 | D35: =D9/$G9 -> 0.98089172 | E35: =E9/$G9 -> 0.98089172 | F35: =F9/$G9 -> 1 | G35: =G9/$G9 -> 1 | H35: =H9/$G9 -> 1 | I35: =I9/$G9 -> 1 | ... M35: =M9/$G9 -> 1 | N35: Munit.yr/PJ
A36: R_APP_CWSH_HEF | H36: =H10/$G9 -> 1.7579618 | I36: =I10/$G9 -> 1.7579618 | J36: =J10/$G9 -> 1.7579618 | K36: =K10/$G9 -> 1.7579618 | L36: =L10/$G9 -> 1.7579618 | M36: =M10/$G9 -> 1.7579618 | N36: Munit.yr/PJ
A37: R_APP_CDRY_EXS | B37: =B11/$G11 -> 0.9624949 | C37: =C11/$G11 -> 0.9624949 | D37: =D11/$G11 -> 0.9624949 | E37: =E11/$G11 -> 0.9624949 | F37: =F11/$G11 -> 1 | G37: =G11/$G11 -> 1 | H37: =H11/$G11 -> 1 | I37: =I11/$G11 -> 1 | ... M37: =M11/$G11 -> 1 | N37: Munit.yr/PJ
A38: R_APP_CDRY_ELC_MEF | B38: =B12/$G11 -> 0.96551181 | C38: =C12/$G11 -> 0.96551181 | D38: =D12/$G11 -> 0.96551181 | E38: =E12/$G11 -> 0.96551181 | F38: =F12/$G11 -> 1.0031641 | G38: =G12/$G11 -> 1.0031641 | H38: =H12/$G11 -> 1.0031641 | I38: =I12/$G11 -> 1.0031641 | ... M38: =M12/$G11 -> 1.0031641 | N38: Munit.yr/PJ
A39: R_APP_CDRY_ELC_HEF | H39: =H13/$G11 -> 1.056953 | I39: =I13/$G11 -> 1.056953 | J39: =J13/$G11 -> 1.056953 | K39: =K13/$G11 -> 1.056953 | L39: =L13/$G11 -> 1.056953 | M39: =M13/$G11 -> 1.056953 | N39: Munit.yr/PJ
A40: R_APP_CDRY_LPG_MEF | B40: =B14/$G11 -> 0.85524445 | C40: =C14/$G11 -> 0.85524445 | D40: =D14/$G11 -> 0.85524445 | E40: =E14/$G11 -> 0.85524445 | F40: =F14/$G11 -> 0.88751782 | G40: =G14/$G11 -> 0.88751782 | H40: =H14/$G11 -> 0.88751782 | I40: =I14/$G11 -> 0.88751782 | ... M40: =M14/$G11 -> 0.88751782 | N40: Munit.yr/PJ
A41: R_APP_CDRY_LPG_HEF | H41: =H15/$G11 -> 0.93592788 | I41: =I15/$G11 -> 0.93592788 | J41: =J15/$G11 -> 0.93592788 | K41: =K15/$G11 -> 0.93592788 | L41: =L15/$G11 -> 0.93592788 | M41: =M15/$G11 -> 0.93592788 | N41: Munit.yr/PJ
...

Sheet stock
A5: Residential Sector
A7: Ontario
A8: Table 31: Appliance Stock by Appliance Type and Energy Source
C11: 2000 | D11: 2001 | E11: 2002 | F11: 2003 | G11: 2004 | H11: 2005 | I11: 2006 | J11: 2007 | K11: 2008 | L11: 2009 | M11: 2010 | N11: 2011 | O11: 2012 | P11: 2013 | Q11: 2014 | R11: 2015 | S11: 2016 | T11: 2017 | U11: 2018 | V11: 2019 | W11: 2020
B13: Appliance Stock by Appliance Type (thousands)
B14: Refrigerator | C14: 5422.759 | D14: 5534.399 | E14: 5642.616 | F14: 5749.344 | G14: 5864.744 | H14: 6080.449 | I14: 6173.67 | J14: 6248.59 | K14: 6357.92 | L14: 6444.731 | M14: 6358.21 | N14: 6450.568 | O14: 6544.548 | P14: 6595.63 | Q14: 6671.664 | R14: 6741 | S14: 6833.448 | T14: 6882.24 | U14: 6992.022 | V14: 7101.804 | W14: 7185.544
B15: Freezer | C15: 2443.942 | D15: 2443.906 | E15: 2437.374 | F15: 2441.559 | G15: 2415.451 | H15: 2402.03 | I15: 2399.793 | J15: 2422.584 | K15: 2430.974 | L15: 2470.039 | M15: 2497.322 | N15: 2531.999 | O15: 2568.888 | P15: 2588.939 | Q15: 2618.784 | R15: 2646 | S15: 2682.288 | T15: 2701.44 | U15: 2744.532 | V15: 2787.624 | W15: 2820.494
B16: Dishwasher | C16: 2073.301 | D16: 2127.048 | E16: 2230.349 | F16: 2321.835 | G16: 2409.201 | H16: 2523.123 | I16: 2612.427 | J16: 2689.103 | K16: 2767.085 | L16: 2848.256 | M16: 2841.522 | N16: 2883.665 | O16: 2925.678 | P16: 2948.514 | Q16: 2982.504 | R16: 3013.5 | S16: 3054.828 | T16: 3076.64 | U16: 3125.717 | V16: 3174.794 | W16: 3212.229
B17: Clothes Washer | C17: 3232.798 | D17: 3300.483 | E17: 3382.795 | F17: 3453.039 | G17: 3506.346 | H17: 3582.668 | I17: 3628.621 | J17: 3665.881 | K17: 3712.065 | L17: 3772.621 | M17: 3771.421 | N17: 3813.07 | O17: 3868.623 | P17: 3898.819 | Q17: 3943.764 | R17: 3984.75 | S17: 4039.398 | T17: 4068.24 | U17: 4133.134 | V17: 4198.029 | W17: 4247.529
B18: Clothes Dryer | C18: 3339.926 | D18: 3389.66 | E18: 3463.124 | F18: 3527.459 | G18: 3583.976 | H18: 3748.573 | I18: 3808.246 | J18: 3870.064 | K18: 3938.661 | L18: 4002.788 | M18: 3922.583 | N18: 3973.159 | O18: 4026.781 | P18: 4053.608 | Q18: 4095.865 | R18: 4134.986 | S18: 4189.249 | T18: 4216.697 | U18: 4282.991 | V18: 4350.237 | W18: 4401.533
B19: Range | C19: 4264.775 | D19: 4351.328 | E19: 4418.371 | F19: 4489.784 | G19: 4559.499 | H19: 4646.321 | I19: 4706.033 | J19: 4784.817 | K19: 4865.068 | L19: 4944.521 | M19: 4955.97 | N19: 5023.807 | O19: 5097 | P19: 5136.783 | Q19: 5196 | R19: 5250 | S19: 5322 | T19: 5360 | U19: 5445.5 | V19: 5531 | W19: 5596.218
B20: Other Appliances1 | C20: 57008.895 | D20: 60852.773 | E20: 63629.531 | F20: 66375.219 | G20: 69828.961 | H20: 74215.812 | I20: 76329.117 | J20: 78934.914 | K20: 80296.812 | L20: 82983.125 | M20: 80887.742 | N20: 83691.602 | O20: 87148.508 | P20: 89883.43 | Q20: 93366.922 | R20: 96883.508 | S20: 99047.742 | T20: 100505.36 | U20: 103159.55 | V20: 105846.74 | W20: 108146.92
B22: Appliances per Household by Appliance Type
B23: Refrigerator | C23: 1.263781 | D23: 1.265078 | E23: 1.267935 | F23: 1.272257 | G23: 1.277446 | H23: 1.301037 | I23: 1.303337 | J23: 1.301174 | K23: 1.303307 | L23: 1.30179 | M23: 1.281346 | N23: 1.284 | O23: 1.284 | P23: 1.284 | Q23: 1.284 | R23: 1.284 | S23: 1.284 | T23: 1.284 | U23: 1.284 | V23: 1.284 | W23: 1.284
B24: Freezer | C24: 0.569564 | D24: 0.558639 | E24: 0.547695 | F24: 0.540286 | G24: 0.526129 | H24: 0.513964 | I24: 0.506625 | J24: 0.504467 | K24: 0.498324 | L24: 0.49893 | M24: 0.503276 | N24: 0.504 | O24: 0.504 | P24: 0.504 | Q24: 0.504 | R24: 0.504 | S24: 0.504 | T24: 0.504 | U24: 0.504 | V24: 0.504 | W24: 0.504
B25: Dishwasher | C25: 0.483186 | D25: 0.48621 | E25: 0.501175 | F25: 0.513793 | G25: 0.524767 | H25: 0.539874 | I25: 0.551515 | J25: 0.559965 | K25: 0.567223 | L25: 0.575327 | M25: 0.572641 | N25: 0.574 | O25: 0.574 | P25: 0.574 | Q25: 0.574 | R25: 0.574 | S25: 0.574 | T25: 0.574 | U25: 0.574 | V25: 0.574 | W25: 0.574
B26: Clothes Washer | C26: 0.753408 | D26: 0.754439 | E26: 0.760138 | F26: 0.764114 | G26: 0.763745 | H26: 0.766586 | I26: 0.766046 | J26: 0.763364 | K26: 0.760934 | L26: 0.762042 | M26: 0.76004 | N26: 0.759 | O26: 0.759 | P26: 0.759 | Q26: 0.759 | R26: 0.759 | S26: 0.759 | T26: 0.759 | U26: 0.759 | V26: 0.759 | W26: 0.759
B27: Clothes Dryer | C27: 0.778374 | D27: 0.774824 | E27: 0.778188 | F27: 0.780582 | G27: 0.780654 | H27: 0.802084 | I27: 0.803967 | J27: 0.805882 | K27: 0.807384 | L27: 0.808535 | M27: 0.790503 | N27: 0.790866 | O27: 0.79003 | P27: 0.789134 | Q27: 0.788273 | R27: 0.787616 | S27: 0.787157 | T27: 0.786697 | U27: 0.786519 | V27: 0.786519 | W27: 0.786519
B28: Range | C28: 0.993912 | D28: 0.994646 | E28: 0.992839 | F28: 0.993533 | G28: 0.993141 | H28: 0.994176 | I28: 0.9935 | J28: 0.996366 | K28: 0.997288 | L28: 0.998758 | M28: 0.998758 | N28: 1 | O28: 1 | P28: 1 | Q28: 1 | R28: 1 | S28: 1 | T28: 1 | U28: 1 | V28: 1 | W28: 1
B29: Other Appliances1 | C29: 13.286 | D29: 13.91 | E29: 14.298 | F29: 14.688 | G29: 15.21 | H29: 15.88 | I29: 16.114001 | J29: 16.437 | K29: 16.46 | L29: 16.761999 | M29: 16.301 | N29: 16.659 | O29: 17.098 | P29: 17.497999 | Q29: 17.968999 | R29: 18.454001 | S29: 18.611 | T29: 18.751 | U29: 18.944 | V29: 19.136999 | W29: 19.325
B31: Stock of Electric Appliances (thousands)
B32: Refrigerator | C32: 5422.759 | D32: 5534.399 | E32: 5642.616 | F32: 5749.344 | G32: 5864.744 | H32: 6080.449 | I32: 6173.67 | J32: 6248.59 | K32: 6357.92 | L32: 6444.731 | M32: 6358.21 | N32: 6450.568 | O32: 6544.548 | P32: 6595.63 | Q32: 6671.664 | R32: 6741 | S32: 6833.448 | T32: 6882.24 | U32: 6992.022 | V32: 7101.804 | W32: 7185.544
B33: Freezer | C33: 2443.942 | D33: 2443.906 | E33: 2437.374 | F33: 2441.559 | G33: 2415.451 | H33: 2402.03 | I33: 2399.793 | J33: 2422.584 | K33: 2430.974 | L33: 2470.039 | M33: 2497.322 | N33: 2531.999 | O33: 2568.888 | P33: 2588.939 | Q33: 2618.784 | R33: 2646 | S33: 2682.288 | T33: 2701.44 | U33: 2744.532 | V33: 2787.624 | W33: 2820.494
B34: Dishwasher | C34: 2073.301 | D34: 2127.048 | E34: 2230.349 | F34: 2321.835 | G34: 2409.201 | H34: 2523.123 | I34: 2612.427 | J34: 2689.103 | K34: 2767.085 | L34: 2848.256 | M34: 2841.522 | N34: 2883.665 | O34: 2925.678 | P34: 2948.514 | Q34: 2982.504 | R34: 3013.5 | S34: 3054.828 | T34: 3076.64 | U34: 3125.717 | V34: 3174.794 | W34: 3212.229
B35: Clothes Washer | C35: 3232.798 | D35: 3300.483 | E35: 3382.795 | F35: 3453.039 | G35: 3506.346 | H35: 3582.668 | I35: 3628.621 | J35: 3665.881 | K35: 3712.065 | L35: 3772.621 | M35: 3771.421 | N35: 3813.07 | O35: 3868.623 | P35: 3898.819 | Q35: 3943.764 | R35: 3984.75 | S35: 4039.398 | T35: 4068.24 | U35: 4133.134 | V35: 4198.029 | W35: 4247.529
B36: Clothes Dryer | C36: 3166.987 | D36: 3220.091 | E36: 3297.466 | F36: 3365.909 | G36: 3426.359 | H36: 3594.483 | I36: 3658.26 | J36: 3724.033 | K36: 3796.199 | L36: 3863.943 | M36: 3788.933 | N36: 3843.212 | O36: 3899.205 | P36: 3929.639 | Q36: 3974.94 | R36: 4016.25 | S36: 4071.33 | T36: 4100.4 | U36: 4165.808 | V36: 4231.215 | W36: 4281.107
B37: Range | C37: 3852.26 | D37: 3915.253 | E37: 3964.064 | F37: 4016.16 | G37: 4055.848 | H37: 4089.882 | I37: 4113.888 | J37: 4147.703 | K37: 4182.869 | L37: 4233.675 | M37: 4247.627 | N37: 4310.426 | O37: 4373.226 | P37: 4407.36 | Q37: 4458.168 | R37: 4504.5 | S37: 4566.276 | T37: 4598.88 | U37: 4672.239 | V37: 4745.598 | W37: 4801.556
B38: Other Appliances1 | C38: 57008.895 | D38: 60852.773 | E38: 63629.531 | F38: 66375.219 | G38: 69828.961 | H38: 74215.812 | I38: 76329.117 | J38: 78934.914 | K38: 80296.812 | L38: 82983.125 | M38: 80887.742 | N38: 83691.602 | O38: 87148.508 | P38: 89883.43 | Q38: 93366.922 | R38: 96883.508 | S38: 99047.742 | T38: 100505.36 | U38: 103159.55 | V38: 105846.74 | W38: 108146.92
B40: Electric Appliances per Household by Appliance Type
B41: Refrigerator | C41: 1.263781 | D41: 1.265078 | E41: 1.267935 | F41: 1.272257 | G41: 1.277446 | H41: 1.301037 | I41: 1.303337 | J41: 1.301174 | K41: 1.303307 | L41: 1.30179 | M41: 1.281346 | N41: 1.284 | O41: 1.284 | P41: 1.284 | Q41: 1.284 | R41: 1.284 | S41: 1.284 | T41: 1.284 | U41: 1.284 | V41: 1.284 | W41: 1.284
B42: Freezer | C42: 0.569564 | D42: 0.558639 | E42: 0.547695 | F42: 0.540286 | G42: 0.526129 | H42: 0.513964 | I42: 0.506625 | J42: 0.504467 | K42: 0.498324 | L42: 0.49893 | M42: 0.503276 | N42: 0.504 | O42: 0.504 | P42: 0.504 | Q42: 0.504 | R42: 0.504 | S42: 0.504 | T42: 0.504 | U42: 0.504 | V42: 0.504 | W42: 0.504
B43: Dishwasher | C43: 0.483186 | D43: 0.48621 | E43: 0.501175 | F43: 0.513793 | G43: 0.524767 | H43: 0.539874 | I43: 0.551515 | J43: 0.559965 | K43: 0.567223 | L43: 0.575327 | M43: 0.572641 | N43: 0.574 | O43: 0.574 | P43: 0.574 | Q43: 0.574 | R43: 0.574 | S43: 0.574 | T43: 0.574 | U43: 0.574 | V43: 0.574 | W43: 0.574
B44: Clothes Washer | C44: 0.753408 | D44: 0.754439 | E44: 0.760138 | F44: 0.764114 | G44: 0.763745 | H44: 0.766586 | I44: 0.766046 | J44: 0.763364 | K44: 0.760934 | L44: 0.762042 | M44: 0.76004 | N44: 0.759 | O44: 0.759 | P44: 0.759 | Q44: 0.759 | R44: 0.759 | S44: 0.759 | T44: 0.759 | U44: 0.759 | V44: 0.759 | W44: 0.759
B45: Clothes Dryer | C45: 0.738071 | D45: 0.736063 | E45: 0.740964 | F45: 0.744833 | G45: 0.746323 | H45: 0.769114 | I45: 0.772303 | J45: 0.775474 | K45: 0.778181 | L45: 0.780489 | M45: 0.763569 | N45: 0.765 | O45: 0.765 | P45: 0.765 | Q45: 0.765 | R45: 0.765 | S45: 0.765 | T45: 0.765 | U45: 0.765 | V45: 0.765 | W45: 0.765
B46: Range | C46: 0.897774 | D46: 0.894966 | E46: 0.890753 | F46: 0.888726 | G46: 0.883437 | H46: 0.875114 | I46: 0.868491 | J46: 0.863696 | K46: 0.857444 | L46: 0.855172 | M46: 0.856008 | N46: 0.858 | O46: 0.858 | P46: 0.858 | Q46: 0.858 | R46: 0.858 | S46: 0.858 | T46: 0.858 | U46: 0.858 | V46: 0.858 | W46: 0.858
B47: Other Appliances1 | C47: 13.286 | D47: 13.91 | E47: 14.298 | F47: 14.688 | G47: 15.21 | H47: 15.88 | I47: 16.114001 | J47: 16.437 | K47: 16.46 | L47: 16.761999 | M47: 16.301 | N47: 16.659 | O47: 17.098 | P47: 17.497999 | Q47: 17.968999 | R47: 18.454001 | S47: 18.611 | T47: 18.751 | U47: 18.944 | V47: 19.136999 | W47: 19.325
B49: Stock of Natural Gas Appliances (thousands)
B50: Clothes Dryer | C50: 172.939 | D50: 169.569 | E50: 165.657 | F50: 161.549 | G50: 157.617 | H50: 154.09 | I50: 149.986 | J50: 146.031 | K50: 142.462 | L50: 138.845 | M50: 133.65 | N50: 129.947 | O50: 127.577 | P50: 123.969 | Q50: 120.925 | R50: 118.736 | S50: 117.919 | T50: 116.297 | U50: 117.183 | V50: 119.023 | W50: 120.426
B51: Range | C51: 412.515 | D51: 436.074 | E51: 454.307 | F51: 473.624 | G51: 503.651 | H51: 556.44 | I51: 592.145 | J51: 637.115 | K51: 682.199 | L51: 710.845 | M51: 708.342 | N51: 713.381 | O51: 723.774 | P51: 729.423 | Q51: 737.832 | R51: 745.5 | S51: 755.724 | T51: 761.12 | U51: 773.261 | V51: 785.402 | W51: 794.663
B53: Natural Gas Appliances per Household by Appliance Type
...

Sheet secondary energy
A5: Residential Sector
A7: Ontario1
A8: Table 13: Appliance Secondary Energy Use and GHG Emissions by Appliance Type
C11: 2000 | D11: 2001 | E11: 2002 | F11: 2003 | G11: 2004 | H11: 2005 | I11: 2006 | J11: 2007 | K11: 2008 | L11: 2009 | M11: 2010 | N11: 2011 | O11: 2012 | P11: 2013 | Q11: 2014 | R11: 2015 | S11: 2016 | T11: 2017 | U11: 2018 | V11: 2019 | W11: 2020
B13: Total Appliance Energy Use (PJ) | C13: 61.844149 | D13: 63.890934 | E13: 60.482749 | F13: 61.946669 | G13: 64.826506 | H13: 60.616106 | I13: 61.323493 | J13: 60.695245 | K13: 61.960848 | L13: 64.432648 | M13: 64.757269 | N13: 64.090173 | O13: 66.04803 | P13: 66.719144 | Q13: 65.574317 | R13: 66.903829 | S13: 61.586904 | T13: 62.230953 | U13: 61.214456 | V13: 62.164526 | W13: 63.938434
B14: Energy Use by Appliance Type (PJ)
B15: Refrigerator | C15: 15.720028 | D15: 15.635089 | E15: 14.212484 | F15: 13.622658 | G15: 13.668285 | H15: 12.301406 | I15: 12.025607 | J15: 11.414944 | K15: 11.284488 | L15: 11.35952 | M15: 10.930443 | N15: 10.277448 | O15: 10.263193 | P15: 10.036843 | Q15: 9.609749 | R15: 9.484849 | S15: 8.518501 | T15: 8.540566 | U15: 8.202577 | V15: 8.427206 | W15: 8.685701
B16: Freezer | C16: 5.419719 | D16: 5.190186 | E16: 4.52661 | F16: 4.356236 | G16: 4.263985 | H16: 3.683391 | I16: 3.526388 | J16: 3.316235 | K16: 3.210387 | L16: 3.211743 | M16: 3.129222 | N16: 2.965072 | O16: 3.000539 | P16: 2.993687 | Q16: 2.925171 | R16: 2.954799 | S16: 2.709578 | T16: 2.725768 | U16: 2.622383 | V16: 2.685636 | W16: 2.75172
B17: Dishwasher2 | C17: 1.462503 | D17: 1.486499 | E17: 1.400445 | F17: 1.424113 | G17: 1.46349 | H17: 1.322186 | I17: 1.298221 | J17: 1.182059 | K17: 1.147282 | L17: 1.151846 | M17: 1.082458 | N17: 0.982966 | O17: 0.94594 | P17: 0.892464 | Q17: 0.829142 | R17: 0.800576 | S17: 0.706604 | T17: 0.691568 | U17: 0.649884 | V17: 0.653078 | W17: 0.659669
B18: Clothes Washer2 | C18: 1.421348 | D18: 1.480225 | E18: 1.408427 | F18: 1.451905 | G18: 1.503047 | H18: 1.351655 | I18: 1.322788 | J18: 1.244148 | K18: 1.14235 | L18: 1.091688 | M18: 1.047109 | N18: 0.942882 | O18: 0.899072 | P18: 0.833668 | Q18: 0.752967 | R18: 0.696221 | S18: 0.582088 | T18: 0.533718 | U18: 0.468413 | V18: 0.444241 | W18: 0.428409
B19: Clothes Dryer | C19: 10.818 | D19: 11.133394 | E19: 10.569353 | F19: 10.945916 | G19: 11.515042 | H19: 10.971228 | I19: 11.096939 | J19: 10.933082 | K19: 11.109894 | L19: 11.486594 | M19: 11.41676 | N19: 11.138082 | O19: 11.397007 | P19: 11.440333 | Q19: 11.224219 | R19: 11.427188 | S19: 10.543854 | T19: 10.530472 | U19: 10.114347 | V19: 10.148489 | W19: 10.28895
B20: Range | C20: 10.980598 | D20: 11.53835 | E20: 11.095946 | F20: 11.566271 | G20: 12.121476 | H20: 11.521593 | I20: 11.638675 | J20: 11.689707 | K20: 11.856219 | L20: 11.952528 | M20: 12.086121 | N20: 12.064969 | O20: 12.003476 | P20: 12.001545 | Q20: 11.56113 | R20: 11.863704 | S20: 10.896173 | T20: 10.923209 | U20: 11.369425 | V20: 10.738253 | W20: 10.940383
B21: Other Appliances3 | C21: 16.021949 | D21: 17.427191 | E21: 17.269484 | F21: 18.579571 | G21: 20.29118 | H21: 19.464648 | I21: 20.414875 | J21: 20.915069 | K21: 22.210229 | L21: 24.178729 | M21: 25.065156 | N21: 25.718754 | O21: 27.538802 | P21: 28.520604 | Q21: 28.671939 | R21: 29.676491 | S21: 27.630107 | T21: 28.285652 | U21: 27.787425 | V21: 29.067624 | W21: 30.183602
B23: Shares (%)
B24: Refrigerator | C24: 25.418781 | D24: 24.471531 | E24: 23.498409 | F24: 21.990944 | G24: 21.084408 | H24: 20.293955 | I24: 19.610113 | J24: 18.806982 | K24: 18.212288 | L24: 17.630068 | M24: 16.879099 | N24: 16.035919 | O24: 15.538984 | P24: 15.043423 | Q24: 14.654745 | R24: 14.176841 | S24: 13.831676 | T24: 13.723985 | U24: 13.399739 | V24: 13.556294 | W24: 13.584476
B25: Freezer | C25: 8.763513 | D25: 8.123509 | E25: 7.484135 | F25: 7.032236 | G25: 6.577533 | H25: 6.076587 | I25: 5.750469 | J25: 5.463748 | K25: 5.181315 | L25: 4.984652 | M25: 4.832233 | N25: 4.626406 | O25: 4.542965 | P25: 4.486999 | Q25: 4.460848 | R25: 4.416487 | S25: 4.399601 | T25: 4.380085 | U25: 4.283928 | V25: 4.320207 | W25: 4.303703
B26: Dishwasher2 | C26: 2.36482 | D26: 2.326619 | E26: 2.315445 | F26: 2.298934 | G26: 2.257549 | H26: 2.181246 | I26: 2.117004 | J26: 1.947532 | K26: 1.851625 | L26: 1.787674 | M26: 1.671562 | N26: 1.533724 | O26: 1.4322 | P26: 1.337643 | Q26: 1.264431 | R26: 1.196607 | S26: 1.147329 | T26: 1.111293 | U26: 1.061651 | V26: 1.050564 | W26: 1.031726
B27: Clothes Washer2 | C27: 2.298275 | D27: 2.3168 | E27: 2.328642 | F27: 2.343798 | G27: 2.318569 | H27: 2.229862 | I27: 2.157066 | J27: 2.049828 | K27: 1.843664 | L27: 1.694309 | M27: 1.616975 | N27: 1.47118 | O27: 1.36124 | P27: 1.249519 | Q27: 1.148265 | R27: 1.04063 | S27: 0.945148 | T27: 0.85764 | U27: 0.765201 | V27: 0.714621 | W27: 0.670034
B28: Clothes Dryer | C28: 17.492359 | D28: 17.425623 | E28: 17.474989 | F28: 17.669903 | G28: 17.762861 | H28: 18.099525 | I28: 18.095739 | J28: 18.013079 | K28: 17.930506 | L28: 17.82729 | M28: 17.630083 | N28: 17.378767 | O28: 17.255636 | P28: 17.147001 | Q28: 17.116793 | R28: 17.080021 | S28: 17.120285 | T28: 16.921598 | U28: 16.522808 | V28: 16.325211 | W28: 16.091963
B29: Range | C29: 17.755274 | D29: 18.059448 | E29: 18.345638 | F29: 18.671335 | G29: 18.698334 | H29: 19.007479 | I29: 18.979145 | J29: 19.259674 | K29: 19.135015 | L29: 18.550421 | M29: 18.663729 | N29: 18.824991 | O29: 18.173861 | P29: 17.988159 | Q29: 17.630575 | R29: 17.732473 | S29: 17.692354 | T29: 17.552694 | U29: 18.573105 | V29: 17.273924 | W29: 17.110809
B30: Other Appliances3 | C30: 25.906977 | D30: 27.276468 | E30: 28.552744 | F30: 29.992849 | G30: 31.300747 | H30: 32.111347 | I30: 33.290462 | J30: 34.459156 | K30: 35.845585 | L30: 37.525585 | M30: 38.706322 | N30: 40.129013 | O30: 41.695114 | P30: 42.747257 | Q30: 43.724342 | R30: 44.356937 | S30: 44.863605 | T30: 45.452705 | U30: 45.39357 | V30: 46.759182 | W30: 47.207291
B32: Activity
B33: Total Households (thousands) | C33: 4290.9 | D33: 4374.75 | E33: 4450.24 | F33: 4519.01 | G33: 4590.99 | H33: 4673.54 | I33: 4736.82 | J33: 4802.27 | K33: 4878.3 | L33: 4950.67 | M33: 4962.134 | N33: 5023.807 | O33: 5097 | P33: 5136.783 | Q33: 5196 | R33: 5250 | S33: 5322 | T33: 5360 | U33: 5445.5 | V33: 5531 | W33: 5596.218
B35: Energy Intensity (GJ/household) | C35: 14.412862 | D35: 14.604477 | E35: 13.590896 | F35: 13.708018 | G35: 14.120376 | H35: 12.970063 | I35: 12.946131 | J35: 12.638866 | K35: 12.70132 | L35: 13.014935 | M35: 13.050286 | N35: 12.757292 | O35: 12.958217 | P35: 12.988506 | Q35: 12.620153 | R35: 12.743586 | S35: 11.572135 | T35: 11.610253 | U35: 11.241292 | V35: 11.239292 | W35: 11.425293
B38: Total Appliance GHG Emissions Excluding Electricity (Mt of CO2e) | C38: 0.119744 | D38: 0.126729 | E38: 0.126972 | F38: 0.133178 | G38: 0.13591 | H38: 0.149278 | I38: 0.156035 | J38: 0.173494 | K38: 0.184499 | L38: 0.176012 | M38: 0.179955 | N38: 0.200222 | O38: 0.194986 | P38: 0.202162 | Q38: 0.193384 | R38: 0.21087 | S38: 0.200241 | T38: 0.202167 | U38: 0.241651 | V38: 0.198815 | W38: 0.201055
B39: GHG Emissions by Appliance Type (Mt of CO2e)
B40: Refrigerator | C40: 0 | D40: 0 | E40: 0 | F40: 0 | G40: 0 | H40: 0 | I40: 0 | J40: 0 | K40: 0 | L40: 0 | M40: 0 | N40: 0 | O40: 0 | P40: 0 | Q40: 0 | R40: 0 | S40: 0 | T40: 0 | U40: 0 | V40: 0 | W40: 0
B41: Freezer | C41: 0 | D41: 0 | E41: 0 | F41: 0 | G41: 0 | H41: 0 | I41: 0 | J41: 0 | K41: 0 | L41: 0 | M41: 0 | N41: 0 | O41: 0 | P41: 0 | Q41: 0 | R41: 0 | S41: 0 | T41: 0 | U41: 0 | V41: 0 | W41: 0
B42: Dishwasher2 | C42: 0 | D42: 0 | E42: 0 | F42: 0 | G42: 0 | H42: 0 | I42: 0 | J42: 0 | K42: 0 | L42: 0 | M42: 0 | N42: 0 | O42: 0 | P42: 0 | Q42: 0 | R42: 0 | S42: 0 | T42: 0 | U42: 0 | V42: 0 | W42: 0
B43: Clothes Washer2 | C43: 0 | D43: 0 | E43: 0 | F43: 0 | G43: 0 | H43: 0 | I43: 0 | J43: 0 | K43: 0 | L43: 0 | M43: 0 | N43: 0 | O43: 0 | P43: 0 | Q43: 0 | R43: 0 | S43: 0 | T43: 0 | U43: 0 | V43: 0 | W43: 0
B44: Clothes Dryer | C44: 0.026577 | D44: 0.026592 | E44: 0.025554 | F44: 0.025599 | G44: 0.024441 | H44: 0.024349 | I44: 0.023685 | J44: 0.024261 | K44: 0.023867 | L44: 0.021526 | M44: 0.021407 | N44: 0.023124 | O44: 0.021889 | P44: 0.021975 | Q44: 0.020355 | R44: 0.021634 | S44: 0.020168 | T44: 0.019981 | U44: 0.023707 | V44: 0.019492 | W44: 0.019728
B45: Range | C45: 0.093167 | D45: 0.100137 | E45: 0.101418 | F45: 0.107579 | G45: 0.11147 | H45: 0.124929 | I45: 0.13235 | J45: 0.149233 | K45: 0.160632 | L45: 0.154487 | M45: 0.158549 | N45: 0.177098 | O45: 0.173098 | P45: 0.180186 | Q45: 0.173029 | R45: 0.189236 | S45: 0.180073 | T45: 0.182186 | U45: 0.217944 | V45: 0.179323 | W45: 0.181326
B46: Other Appliances3 | C46: 0 | D46: 0 | E46: 0 | F46: 0 | G46: 0 | H46: 0 | I46: 0 | J46: 0 | K46: 0 | L46: 0 | M46: 0 | N46: 0 | O46: 0 | P46: 0 | Q46: 0 | R46: 0 | S46: 0 | T46: 0 | U46: 0 | V46: 0 | W46: 0
B48: GHG Intensity (tonne/TJ) | C48: 1.936214 | D48: 1.983514 | E48: 2.09931 | F48: 2.149881 | G48: 2.096522 | H48: 2.462676 | I48: 2.54446 | J48: 2.858444 | K48: 2.977678 | L48: 2.731727 | M48: 2.778923 | N48: 3.124069 | O48: 2.952189 | P48: 3.030038 | Q48: 2.949078 | R48: 3.151831 | S48: 3.251357 | T48: 3.248663 | U48: 3.947615 | V48: 3.198213 | W48: 3.144502
B51: Heat Loss by Appliance Type (PJ)
B52: Refrigerator | C52: 6.446441 | D52: 5.763626 | E52: 5.560101 | F52: 5.749076 | G52: 5.56672 | H52: 4.973856 | I52: 4.349411 | J52: 4.543644 | K52: 4.619877 | L52: 4.654387 | M52: 4.059283 | N52: 3.912865 | O52: 3.543482 | P52: 4.017667 | Q52: 4.182105 | R52: 3.814186 | S52: 3.284625 | T52: 3.434563 | U52: 3.303606 | V52: 3.520895 | W52: 3.188744
B53: Freezer | C53: 2.222509 | D53: 1.913279 | E53: 1.770866 | F53: 1.838432 | G53: 1.736605 | H53: 1.489314 | I53: 1.275421 | J53: 1.320006 | K53: 1.314334 | L53: 1.315962 | M53: 1.162112 | N53: 1.128872 | O53: 1.03597 | P53: 1.198349 | Q53: 1.273017 | R53: 1.188227 | S53: 1.044778 | T53: 1.096159 | U53: 1.056171 | V53: 1.122062 | W53: 1.010227
B54: Dishwasher2 | C54: 0.199913 | D54: 0.182658 | E54: 0.182624 | F54: 0.200336 | G54: 0.19868 | H54: 0.178201 | I54: 0.156513 | J54: 0.156837 | K54: 0.156566 | L54: 0.157317 | M54: 0.133999 | N54: 0.124746 | O54: 0.108865 | P54: 0.119082 | Q54: 0.120279 | R54: 0.107313 | S54: 0.090819 | T54: 0.092704 | U54: 0.087247 | V54: 0.090952 | W54: 0.080727
B55: Clothes Washer2 | C55: 0.323813 | D55: 0.303145 | E55: 0.306108 | F55: 0.34041 | G55: 0.340083 | H55: 0.303621 | I55: 0.265792 | J55: 0.275125 | K55: 0.259821 | L55: 0.248501 | M55: 0.216038 | N55: 0.199432 | O55: 0.172453 | P55: 0.185395 | Q55: 0.182048 | R55: 0.155541 | S55: 0.124692 | T55: 0.119241 | U55: 0.104808 | V55: 0.103113 | W55: 0.087378
B56: Clothes Dryer | C56: 1.232285 | D56: 1.140041 | E56: 1.148573 | F56: 1.283175 | G56: 1.302712 | H56: 1.232228 | I56: 1.11487 | J56: 1.208845 | K56: 1.263444 | L56: 1.307348 | M56: 1.177747 | N56: 1.177925 | O56: 1.09304 | P56: 1.272076 | Q56: 1.356865 | R56: 1.276463 | S56: 1.129326 | T56: 1.176333 | U56: 1.131549 | V56: 1.177791 | W56: 1.049261
...
